Workbook
Name _low1: #REF!
Name _low1: #REF!
Name _low2: #REF!
Name _low2: #REF!
Name _LOW3: #REF!
Name _LOW3: #REF!
Name _pl1: #REF!
Name _pl1: #REF!
Name _XX37: #REF!
Name _XX37: #REF!
Name _XX39: #REF!
Name _XX39: #REF!
Name bs: #REF!
Name bs: #REF!
Name bscf1: #REF!
Name bscf1: #REF!
Name bscf2: #REF!
Name bscf2: #REF!
Name BSCF3: #REF!
Name BSCF3: #REF!
Name content: #REF!
Name content: #REF!
Name date: #REF!
Name date: #REF!
Name dicf: #REF!
Name dicf: #REF!
Name expenses: #REF!
Name expenses: #REF!
Name file: #REF!
Name file: #REF!
Name file1: #REF!
Name file1: #REF!
Name 경영현황비교2: #REF!
Name 대차대조표1: #REF!
Name 대차대조표1: #REF!
Name 대차대조표2: #REF!
Name 대차대조표2: #REF!
Name 대차대조표둘: #REF!
Name 대차대조표둘: #REF!
Name 손익계산서: #REF!
Name 손익계산서: #REF!
Name 현금흐름표: #REF!
Name 현금흐름표: #REF!

Sheet 목표
B5: 2026 매출매입 | C5: Q1 | D5: Q2 | E5: Q3 | F5: Q4 | G5: Total
B6: 목표 TST | C6: =570000000+750000000 -> 1320000000 | D6: =280000000+60000000 -> 340000000 | E6: =250000000+220000000 -> 470000000 | F6: =740000000+330000000 -> 1070000000 | G6: =SUM(C6:F6) -> 3200000000
B7: 목표 SDT | C7: 250000000 | D7: 215000000 | E7: 75000000 | F7: 410000000 | G7: =SUM(C7:F7) -> 950000000
B8: 목표 EST1 | C8: =350000000 -> 350000000 | D8: 300000000 | E8: 350000000 | F8: 400000000 | G8: =SUM(C8:F8) -> 1400000000
B9: 목표 EST2+EST3 | C9: =150000000 -> 150000000 | D9: =80000000 -> 80000000 | E9: =40000000 -> 40000000 | F9: =130000000 -> 130000000 | G9: =SUM(C9:F9) -> 400000000

Sheet 팀별실적
B1: 구분 | D1: 팀명 | E1: 1월 | F1: 2월 | G1: 3월 | H1: Q1 | I1: 4월 | J1: 5월 | K1: 6월 | L1: Q2 | M1: 7월 | N1: 8월 | O1: 9월 | P1: Q3 | Q1: 10월 | R1: 11월 | S1: 12월 | T1: Q4 | U1: 2026
B2: 매출 | D2: SDT | E2: =SDT!F12 -> 1600000 | F2: =SDT!G12 -> 30000000 | G2: =SDT!H12 -> 30000000 | H2: =SUM(E2:G2) -> 61600000 | I2: =SDT!J12 -> 30000000 | J2: =SDT!K12 -> 30000000 | K2: =SDT!L12 -> 30000000 | L2: =SUM(I2:K2) -> 90000000 | M2: =SDT!N12 -> 30000000 | N2: =SDT!O12 -> 30000000 | O2: =SDT!P12 -> 30000000 | P2: =SUM(M2:O2) -> 90000000 | Q2: =SDT!R12 -> 30000000 | R2: =SDT!S12 -> 30000000 | S2: =SDT!T12 -> 30000000 | T2: =SUM(Q2:S2) -> 90000000 | U2: =H2+L2+P2+T2 -> 331600000
D3: TST1 | E3: ='TST1'!F12 -> 535987000 | F3: ='TST1'!G12 -> 68000000 | G3: ='TST1'!H12 -> 68000000 | H3: =SUM(E3:G3) -> 671987000 | I3: ='TST1'!J12 -> 68000000 | J3: ='TST1'!K12 -> 68000000 | K3: ='TST1'!L12 -> 68000000 | L3: =SUM(I3:K3) -> 204000000 | M3: ='TST1'!N12 -> 68000000 | N3: ='TST1'!O12 -> 68000000 | O3: ='TST1'!P12 -> 68000000 | P3: =SUM(M3:O3) -> 204000000 | Q3: ='TST1'!R12 -> 68000000 | R3: ='TST1'!S12 -> 68000000 | S3: ='TST1'!T12 -> 68000000 | T3: =SUM(Q3:S3) -> 204000000 | U3: =H3+L3+P3+T3 -> 1283987000
D4: TST2 | E4: ='TST2'!F12 -> 581480000 | F4: ='TST2'!G12 -> 155000000 | G4: ='TST2'!H12 -> 155000000 | H4: =SUM(E4:G4) -> 891480000 | I4: ='TST2'!J12 -> 155000000 | J4: ='TST2'!K12 -> 155000000 | K4: ='TST2'!L12 -> 155000000 | L4: =SUM(I4:K4) -> 465000000 | M4: ='TST2'!N12 -> 155000000 | N4: ='TST2'!O12 -> 155000000 | O4: ='TST2'!P12 -> 155000000 | P4: =SUM(M4:O4) -> 465000000 | Q4: ='TST2'!R12 -> 155000000 | R4: ='TST2'!S12 -> 155000000 | S4: ='TST2'!T12 -> 155000000 | T4: =SUM(Q4:S4) -> 465000000 | U4: =H4+L4+P4+T4 -> 2286480000
D5: EST1 | E5: ='EST1'!F12 -> 0 | F5: ='EST1'!G12 -> 120000000 | G5: ='EST1'!H12 -> 120000000 | H5: =SUM(E5:G5) -> 240000000 | I5: ='EST1'!J12 -> 120000000 | J5: ='EST1'!K12 -> 120000000 | K5: ='EST1'!L12 -> 120000000 | L5: =SUM(I5:K5) -> 360000000 | M5: ='EST1'!N12 -> 120000000 | N5: ='EST1'!O12 -> 120000000 | O5: ='EST1'!P12 -> 120000000 | P5: =SUM(M5:O5) -> 360000000 | Q5: ='EST1'!R12 -> 120000000 | R5: ='EST1'!S12 -> 120000000 | S5: ='EST1'!T12 -> 120000000 | T5: =SUM(Q5:S5) -> 360000000 | U5: =H5+L5+P5+T5 -> 1320000000
D6: EST2 | E6: ='EST2'!F12 -> 0 | F6: ='EST2'!G12 -> 5000000 | G6: ='EST2'!H12 -> 5000000 | H6: =SUM(E6:G6) -> 10000000 | I6: ='EST2'!J12 -> 5000000 | J6: ='EST2'!K12 -> 5000000 | K6: ='EST2'!L12 -> 5000000 | L6: =SUM(I6:K6) -> 15000000 | M6: ='EST2'!N12 -> 5000000 | N6: ='EST2'!O12 -> 5000000 | O6: ='EST2'!P12 -> 5000000 | P6: =SUM(M6:O6) -> 15000000 | Q6: ='EST2'!R12 -> 5000000 | R6: ='EST2'!S12 -> 5000000 | S6: ='EST2'!T12 -> 5000000 | T6: =SUM(Q6:S6) -> 15000000 | U6: =H6+L6+P6+T6 -> 55000000
D7: EST3 | E7: ='EST3'!F12 -> 0 | F7: ='EST3'!G12 -> 1000000 | G7: ='EST3'!H12 -> 1000000 | H7: =SUM(E7:G7) -> 2000000 | I7: ='EST3'!J12 -> 1000000 | J7: ='EST3'!K12 -> 1000000 | K7: ='EST3'!L12 -> 1000000 | L7: =SUM(I7:K7) -> 3000000 | M7: ='EST3'!N12 -> 1000000 | N7: ='EST3'!O12 -> 1000000 | O7: ='EST3'!P12 -> 1000000 | P7: =SUM(M7:O7) -> 3000000 | Q7: ='EST3'!R12 -> 1000000 | R7: ='EST3'!S12 -> 1000000 | S7: ='EST3'!T12 -> 1000000 | T7: =SUM(Q7:S7) -> 3000000 | U7: =H7+L7+P7+T7 -> 11000000
B8: 계 | E8: =SUM(E2:E7) -> 1119067000 | F8: =SUM(F2:F7) -> 379000000 | G8: =SUM(G2:G7) -> 379000000 | H8: =SUM(H2:H7) -> 1877067000 | I8: =SUM(I2:I7) -> 379000000 | J8: =SUM(J2:J7) -> 379000000 | K8: =SUM(K2:K7) -> 379000000 | L8: =SUM(L2:L7) -> 1137000000 | ... U8: =SUM(U2:U7) -> 5288067000
B9: 매입 | D9: SDT | E9: =SDT!F26 -> 86000 | F9: =SDT!G26 -> 80000 | G9: =SDT!H26 -> 80000 | H9: =SUM(E9:G9) -> 246000 | I9: =SDT!J26 -> 80000 | J9: =SDT!K26 -> 80000 | K9: =SDT!L26 -> 80000 | L9: =SUM(I9:K9) -> 240000 | M9: =SDT!N26 -> 80000 | N9: =SDT!O26 -> 80000 | O9: =SDT!P26 -> 80000 | P9: =SUM(M9:O9) -> 240000 | Q9: =SDT!R26 -> 80000 | R9: =SDT!S26 -> 80000 | S9: =SDT!T26 -> 80000 | T9: =SUM(Q9:S9) -> 240000 | U9: =H9+L9+P9+T9 -> 966000
D10: TST1 | E10: ='TST1'!F26 -> 234537000 | F10: ='TST1'!G26 -> 30995000 | G10: ='TST1'!H26 -> 30995000 | H10: =SUM(E10:G10) -> 296527000 | I10: ='TST1'!J26 -> 30995000 | J10: ='TST1'!K26 -> 30995000 | K10: ='TST1'!L26 -> 30995000 | L10: =SUM(I10:K10) -> 92985000 | M10: ='TST1'!N26 -> 30995000 | N10: ='TST1'!O26 -> 30995000 | O10: ='TST1'!P26 -> 30995000 | P10: =SUM(M10:O10) -> 92985000 | Q10: ='TST1'!R26 -> 30995000 | R10: ='TST1'!S26 -> 30995000 | S10: ='TST1'!T26 -> 30995000 | T10: =SUM(Q10:S10) -> 92985000 | U10: =H10+L10+P10+T10 -> 575482000
D11: TST2 | E11: ='TST2'!F26 -> 101545000 | F11: ='TST2'!G26 -> 78029000 | G11: ='TST2'!H26 -> 78029000 | H11: =SUM(E11:G11) -> 257603000 | I11: ='TST2'!J26 -> 78029000 | J11: ='TST2'!K26 -> 78029000 | K11: ='TST2'!L26 -> 78029000 | L11: =SUM(I11:K11) -> 234087000 | M11: ='TST2'!N26 -> 78029000 | N11: ='TST2'!O26 -> 78029000 | O11: ='TST2'!P26 -> 78029000 | P11: =SUM(M11:O11) -> 234087000 | Q11: ='TST2'!R26 -> 78029000 | R11: ='TST2'!S26 -> 78029000 | S11: ='TST2'!T26 -> 78029000 | T11: =SUM(Q11:S11) -> 234087000 | U11: =H11+L11+P11+T11 -> 959864000
D12: EST1 | E12: ='EST1'!F26 -> 1100000 | F12: ='EST1'!G26 -> 2100000 | G12: ='EST1'!H26 -> 2100000 | H12: =SUM(E12:G12) -> 5300000 | I12: ='EST1'!J26 -> 2100000 | J12: ='EST1'!K26 -> 2100000 | K12: ='EST1'!L26 -> 2100000 | L12: =SUM(I12:K12) -> 6300000 | M12: ='EST1'!N26 -> 2100000 | N12: ='EST1'!O26 -> 2100000 | O12: ='EST1'!P26 -> 2100000 | P12: =SUM(M12:O12) -> 6300000 | Q12: ='EST1'!R26 -> 2100000 | R12: ='EST1'!S26 -> 2100000 | S12: ='EST1'!T26 -> 2100000 | T12: =SUM(Q12:S12) -> 6300000 | U12: =H12+L12+P12+T12 -> 24200000
D13: EST2 | E13: ='EST2'!F26 -> 2081000 | F13: ='EST2'!G26 -> 0 | G13: ='EST2'!H26 -> 0 | H13: =SUM(E13:G13) -> 2081000 | I13: ='EST2'!J26 -> 0 | J13: ='EST2'!K26 -> 0 | K13: ='EST2'!L26 -> 0 | L13: =SUM(I13:K13) -> 0 | M13: ='EST2'!N26 -> 0 | N13: ='EST2'!O26 -> 0 | O13: ='EST2'!P26 -> 0 | P13: =SUM(M13:O13) -> 0 | Q13: ='EST2'!R26 -> 0 | R13: ='EST2'!S26 -> 0 | S13: ='EST2'!T26 -> 0 | T13: =SUM(Q13:S13) -> 0 | U13: =H13+L13+P13+T13 -> 2081000
D14: EST3 | E14: ='EST3'!F26 -> 0 | F14: ='EST3'!G26 -> 0 | G14: ='EST3'!H26 -> 0 | H14: =SUM(E14:G14) -> 0 | I14: ='EST3'!J26 -> 0 | J14: ='EST3'!K26 -> 0 | K14: ='EST3'!L26 -> 0 | L14: =SUM(I14:K14) -> 0 | M14: ='EST3'!N26 -> 0 | N14: ='EST3'!O26 -> 0 | O14: ='EST3'!P26 -> 0 | P14: =SUM(M14:O14) -> 0 | Q14: ='EST3'!R26 -> 0 | R14: ='EST3'!S26 -> 0 | S14: ='EST3'!T26 -> 0 | T14: =SUM(Q14:S14) -> 0 | U14: =H14+L14+P14+T14 -> 0
B15: 계 | E15: =SUM(E9:E14) -> 339349000 | F15: =SUM(F9:F14) -> 111204000 | G15: =SUM(G9:G14) -> 111204000 | H15: =SUM(H9:H14) -> 561757000 | I15: =SUM(I9:I14) -> 111204000 | J15: =SUM(J9:J14) -> 111204000 | K15: =SUM(K9:K14) -> 111204000 | L15: =SUM(L9:L14) -> 333612000 | ... U15: =SUM(U9:U14) -> 1562593000
B16: 매출이익 | D16: 예산 | H16: 2070000000 | L16: 935000000 | P16: 935000000 | T16: 2010000000 | U16: =T16+P16+L16+H16 -> 5950000000
D17: SDT | E17: =E2-E9 -> 1514000 | F17: =F2-F9 -> 29920000 | G17: =G2-G9 -> 29920000 | H17: =SUM(E17:G17) -> 61354000 | I17: =I2-I9 -> 29920000 | J17: =J2-J9 -> 29920000 | K17: =K2-K9 -> 29920000 | L17: =SUM(I17:K17) -> 89760000 | M17: =M2-M9 -> 29920000 | N17: =N2-N9 -> 29920000 | O17: =O2-O9 -> 29920000 | P17: =SUM(M17:O17) -> 89760000 | Q17: =Q2-Q9 -> 29920000 | R17: =R2-R9 -> 29920000 | S17: =S2-S9 -> 29920000 | T17: =SUM(Q17:S17) -> 89760000 | U17: =H17+L17+P17+T17 -> 330634000
D18: TST1 | E18: =E3-E10 -> 301450000 | F18: =F3-F10 -> 37005000 | G18: =G3-G10 -> 37005000 | H18: =SUM(E18:G18) -> 375460000 | I18: =I3-I10 -> 37005000 | J18: =J3-J10 -> 37005000 | K18: =K3-K10 -> 37005000 | L18: =SUM(I18:K18) -> 111015000 | M18: =M3-M10 -> 37005000 | N18: =N3-N10 -> 37005000 | O18: =O3-O10 -> 37005000 | P18: =SUM(M18:O18) -> 111015000 | Q18: =Q3-Q10 -> 37005000 | R18: =R3-R10 -> 37005000 | S18: =S3-S10 -> 37005000 | T18: =SUM(Q18:S18) -> 111015000 | U18: =H18+L18+P18+T18 -> 708505000
D19: TST2 | E19: =E4-E11 -> 479935000 | F19: =F4-F11 -> 76971000 | G19: =G4-G11 -> 76971000 | H19: =SUM(E19:G19) -> 633877000 | I19: =I4-I11 -> 76971000 | J19: =J4-J11 -> 76971000 | K19: =K4-K11 -> 76971000 | L19: =SUM(I19:K19) -> 230913000 | M19: =M4-M11 -> 76971000 | N19: =N4-N11 -> 76971000 | O19: =O4-O11 -> 76971000 | P19: =SUM(M19:O19) -> 230913000 | Q19: =Q4-Q11 -> 76971000 | R19: =R4-R11 -> 76971000 | S19: =S4-S11 -> 76971000 | T19: =SUM(Q19:S19) -> 230913000 | U19: =H19+L19+P19+T19 -> 1326616000
D20: EST1 | E20: =E5-E12 -> -1100000 | F20: =F5-F12 -> 117900000 | G20: =G5-G12 -> 117900000 | H20: =SUM(E20:G20) -> 234700000 | I20: =I5-I12 -> 117900000 | J20: =J5-J12 -> 117900000 | K20: =K5-K12 -> 117900000 | L20: =SUM(I20:K20) -> 353700000 | M20: =M5-M12 -> 117900000 | N20: =N5-N12 -> 117900000 | O20: =O5-O12 -> 117900000 | P20: =SUM(M20:O20) -> 353700000 | Q20: =Q5-Q12 -> 117900000 | R20: =R5-R12 -> 117900000 | S20: =S5-S12 -> 117900000 | T20: =SUM(Q20:S20) -> 353700000 | U20: =H20+L20+P20+T20 -> 1295800000
D21: EST2 | E21: =E6-E13 -> -2081000 | F21: =F6-F13 -> 5000000 | G21: =G6-G13 -> 5000000 | H21: =SUM(E21:G21) -> 7919000 | I21: =I6-I13 -> 5000000 | J21: =J6-J13 -> 5000000 | K21: =K6-K13 -> 5000000 | L21: =SUM(I21:K21) -> 15000000 | M21: =M6-M13 -> 5000000 | N21: =N6-N13 -> 5000000 | O21: =O6-O13 -> 5000000 | P21: =SUM(M21:O21) -> 15000000 | Q21: =Q6-Q13 -> 5000000 | R21: =R6-R13 -> 5000000 | S21: =S6-S13 -> 5000000 | T21: =SUM(Q21:S21) -> 15000000 | U21: =H21+L21+P21+T21 -> 52919000
D22: EST3 | E22: =E7-E14 -> 0 | F22: =F7-F14 -> 1000000 | G22: =G7-G14 -> 1000000 | H22: =SUM(E22:G22) -> 2000000 | I22: =I7-I14 -> 1000000 | J22: =J7-J14 -> 1000000 | K22: =K7-K14 -> 1000000 | L22: =SUM(I22:K22) -> 3000000 | M22: =M7-M14 -> 1000000 | N22: =N7-N14 -> 1000000 | O22: =O7-O14 -> 1000000 | P22: =SUM(M22:O22) -> 3000000 | Q22: =Q7-Q14 -> 1000000 | R22: =R7-R14 -> 1000000 | S22: =S7-S14 -> 1000000 | T22: =SUM(Q22:S22) -> 3000000 | U22: =H22+L22+P22+T22 -> 11000000
B23: 계 | E23: =SUM(E17:E22) -> 779718000 | F23: =SUM(F17:F22) -> 267796000 | G23: =SUM(G17:G22) -> 267796000 | H23: =SUM(H17:H22) -> 1315310000 | I23: =SUM(I17:I22) -> 267796000 | J23: =SUM(J17:J22) -> 267796000 | K23: =SUM(K17:K22) -> 267796000 | L23: =SUM(L17:L22) -> 803388000 | ... U23: =SUM(U17:U22) -> 3725474000
B24: 직접 비용 | D24: SDT | E24: =SDT!F124 -> 33217000 | F24: =SDT!G124 -> 33247000 | G24: =SDT!H124 -> 33247000 | H24: =SUM(E24:G24) -> 99711000 | I24: =SDT!J124 -> 33247000 | J24: =SDT!K124 -> 33247000 | K24: =SDT!L124 -> 33247000 | L24: =SUM(I24:K24) -> 99741000 | M24: =SDT!N124 -> 33247000 | N24: =SDT!O124 -> 33247000 | O24: =SDT!P124 -> 33247000 | P24: =SUM(M24:O24) -> 99741000 | Q24: =SDT!R124 -> 33247000 | R24: =SDT!S124 -> 33247000 | S24: =SDT!T124 -> 33247000 | T24: =SUM(Q24:S24) -> 99741000 | U24: =H24+L24+P24+T24 -> 398934000
D25: TST1 | E25: ='TST1'!F124 -> 46146000 | F25: ='TST1'!G124 -> 46709000 | G25: ='TST1'!H124 -> 46709000 | H25: =SUM(E25:G25) -> 139564000 | I25: ='TST1'!J124 -> 46709000 | J25: ='TST1'!K124 -> 46709000 | K25: ='TST1'!L124 -> 46709000 | L25: =SUM(I25:K25) -> 140127000 | M25: ='TST1'!N124 -> 46709000 | N25: ='TST1'!O124 -> 46709000 | O25: ='TST1'!P124 -> 46709000 | P25: =SUM(M25:O25) -> 140127000 | Q25: ='TST1'!R124 -> 46709000 | R25: ='TST1'!S124 -> 46709000 | S25: ='TST1'!T124 -> 46709000 | T25: =SUM(Q25:S25) -> 140127000 | U25: =H25+L25+P25+T25 -> 559945000
D26: TST2 | E26: ='TST2'!F124 -> 28732000 | F26: ='TST2'!G124 -> 29254000 | G26: ='TST2'!H124 -> 29254000 | H26: =SUM(E26:G26) -> 87240000 | I26: ='TST2'!J124 -> 29254000 | J26: ='TST2'!K124 -> 29254000 | K26: ='TST2'!L124 -> 29254000 | L26: =SUM(I26:K26) -> 87762000 | M26: ='TST2'!N124 -> 29254000 | N26: ='TST2'!O124 -> 29254000 | O26: ='TST2'!P124 -> 29254000 | P26: =SUM(M26:O26) -> 87762000 | Q26: ='TST2'!R124 -> 29254000 | R26: ='TST2'!S124 -> 29254000 | S26: ='TST2'!T124 -> 29254000 | T26: =SUM(Q26:S26) -> 87762000 | U26: =H26+L26+P26+T26 -> 350526000
D27: EST1 | E27: ='EST1'!F124 -> 43911000 | F27: ='EST1'!G124 -> 43846000 | G27: ='EST1'!H124 -> 43846000 | H27: =SUM(E27:G27) -> 131603000 | I27: ='EST1'!J124 -> 43846000 | J27: ='EST1'!K124 -> 43846000 | K27: ='EST1'!L124 -> 43846000 | L27: =SUM(I27:K27) -> 131538000 | M27: ='EST1'!N124 -> 43846000 | N27: ='EST1'!O124 -> 43846000 | O27: ='EST1'!P124 -> 43846000 | P27: =SUM(M27:O27) -> 131538000 | Q27: ='EST1'!R124 -> 43846000 | R27: ='EST1'!S124 -> 43846000 | S27: ='EST1'!T124 -> 43846000 | T27: =SUM(Q27:S27) -> 131538000 | U27: =H27+L27+P27+T27 -> 526217000
D28: EST2 | E28: ='EST2'!F124 -> 30893000 | F28: ='EST2'!G124 -> 30847000 | G28: ='EST2'!H124 -> 30847000 | H28: =SUM(E28:G28) -> 92587000 | I28: ='EST2'!J124 -> 30847000 | J28: ='EST2'!K124 -> 30847000 | K28: ='EST2'!L124 -> 30847000 | L28: =SUM(I28:K28) -> 92541000 | M28: ='EST2'!N124 -> 30847000 | N28: ='EST2'!O124 -> 30847000 | O28: ='EST2'!P124 -> 30847000 | P28: =SUM(M28:O28) -> 92541000 | Q28: ='EST2'!R124 -> 30847000 | R28: ='EST2'!S124 -> 30847000 | S28: ='EST2'!T124 -> 30847000 | T28: =SUM(Q28:S28) -> 92541000 | U28: =H28+L28+P28+T28 -> 370210000
D29: EST3 | E29: ='EST3'!F124 -> 16434000 | F29: ='EST3'!G124 -> 16410000 | G29: ='EST3'!H124 -> 16410000 | H29: =SUM(E29:G29) -> 49254000 | I29: ='EST3'!J124 -> 16410000 | J29: ='EST3'!K124 -> 16410000 | K29: ='EST3'!L124 -> 16410000 | L29: =SUM(I29:K29) -> 49230000 | M29: ='EST3'!N124 -> 16410000 | N29: ='EST3'!O124 -> 16410000 | O29: ='EST3'!P124 -> 16410000 | P29: =SUM(M29:O29) -> 49230000 | Q29: ='EST3'!R124 -> 16410000 | R29: ='EST3'!S124 -> 16410000 | S29: ='EST3'!T124 -> 16410000 | T29: =SUM(Q29:S29) -> 49230000 | U29: =H29+L29+P29+T29 -> 196944000
B30: 소계 | E30: =SUM(E24:E29) -> 199333000 | F30: =SUM(F24:F29) -> 200313000 | G30: =SUM(G24:G29) -> 200313000 | H30: =SUM(H24:H29) -> 599959000 | I30: =SUM(I24:I29) -> 200313000 | J30: =SUM(J24:J29) -> 200313000 | K30: =SUM(K24:K29) -> 200313000 | L30: =SUM(L24:L29) -> 600939000 | ... U30: =SUM(U24:U29) -> 2402776000
B31: 간접 비용 | D31: SDT | E31: =ROUND((간접!$F$124*팀별실적!E24)/팀별실적!$E$30,-3) -> 9888000 | F31: =ROUND((간접!$G$124*팀별실적!F24)/팀별실적!$F$30,-3) -> 9514000 | G31: =ROUND((간접!$H$124*팀별실적!G24)/팀별실적!$G$30,-3) -> 9514000 | H31: =SUM(E31:G31) -> 28916000 | I31: =ROUND((간접!$J$124*팀별실적!I24)/팀별실적!$I$30,-3) -> 9514000 | J31: =ROUND((간접!$K$124*팀별실적!J24)/팀별실적!$J$30,-3) -> 9514000 | K31: =ROUND((간접!$L$124*팀별실적!K24)/팀별실적!$K$30,-3) -> 9514000 | L31: =SUM(I31:K31) -> 28542000 | M31: =ROUND((간접!$N$124*팀별실적!M24)/팀별실적!$M$30,-3) -> 9514000 | N31: =ROUND((간접!$O$124*팀별실적!N24)/팀별실적!$N$30,-3) -> 9514000 | O31: =ROUND((간접!$P$124*팀별실적!O24)/팀별실적!$O$30,-3) -> 9514000 | P31: =SUM(M31:O31) -> 28542000 | Q31: =ROUND((간접!$R$124*팀별실적!Q24)/팀별실적!$Q$30,-3) -> 9514000 | R31: =ROUND((간접!$S$124*팀별실적!R24)/팀별실적!$R$30,-3) -> 9514000 | S31: =ROUND((간접!$T$124*팀별실적!S24)/팀별실적!$S$30,-3) -> 9514000 | T31: =SUM(Q31:S31) -> 28542000 | U31: =H31+L31+P31+T31 -> 114542000
D32: TST1 | E32: =ROUND((간접!$F$124*팀별실적!E25)/팀별실적!$E$30,-3) -> 13736000 | F32: =ROUND((간접!$G$124*팀별실적!F25)/팀별실적!$F$30,-3) -> 13366000 | G32: =ROUND((간접!$H$124*팀별실적!G25)/팀별실적!$G$30,-3) -> 13366000 | H32: =SUM(E32:G32) -> 40468000 | I32: =ROUND((간접!$J$124*팀별실적!I25)/팀별실적!$I$30,-3) -> 13366000 | J32: =ROUND((간접!$K$124*팀별실적!J25)/팀별실적!$J$30,-3) -> 13366000 | K32: =ROUND((간접!$L$124*팀별실적!K25)/팀별실적!$K$30,-3) -> 13366000 | L32: =SUM(I32:K32) -> 40098000 | M32: =ROUND((간접!$N$124*팀별실적!M25)/팀별실적!$M$30,-3) -> 13366000 | N32: =ROUND((간접!$O$124*팀별실적!N25)/팀별실적!$N$30,-3) -> 13366000 | O32: =ROUND((간접!$P$124*팀별실적!O25)/팀별실적!$O$30,-3) -> 13366000 | P32: =SUM(M32:O32) -> 40098000 | Q32: =ROUND((간접!$R$124*팀별실적!Q25)/팀별실적!$Q$30,-3) -> 13366000 | R32: =ROUND((간접!$S$124*팀별실적!R25)/팀별실적!$R$30,-3) -> 13366000 | S32: =ROUND((간접!$T$124*팀별실적!S25)/팀별실적!$S$30,-3) -> 13366000 | T32: =SUM(Q32:S32) -> 40098000 | U32: =H32+L32+P32+T32 -> 160762000
D33: TST2 | E33: =ROUND((간접!$F$124*팀별실적!E26)/팀별실적!$E$30,-3)-1000 -> 8552000 | F33: =ROUND((간접!$G$124*팀별실적!F26)/팀별실적!$F$30,-3) -> 8371000 | G33: =ROUND((간접!$H$124*팀별실적!G26)/팀별실적!$G$30,-3) -> 8371000 | H33: =SUM(E33:G33) -> 25294000 | I33: =ROUND((간접!$J$124*팀별실적!I26)/팀별실적!$I$30,-3) -> 8371000 | J33: =ROUND((간접!$K$124*팀별실적!J26)/팀별실적!$J$30,-3) -> 8371000 | K33: =ROUND((간접!$L$124*팀별실적!K26)/팀별실적!$K$30,-3) -> 8371000 | L33: =SUM(I33:K33) -> 25113000 | M33: =ROUND((간접!$N$124*팀별실적!M26)/팀별실적!$M$30,-3) -> 8371000 | N33: =ROUND((간접!$O$124*팀별실적!N26)/팀별실적!$N$30,-3) -> 8371000 | O33: =ROUND((간접!$P$124*팀별실적!O26)/팀별실적!$O$30,-3) -> 8371000 | P33: =SUM(M33:O33) -> 25113000 | Q33: =ROUND((간접!$R$124*팀별실적!Q26)/팀별실적!$Q$30,-3) -> 8371000 | R33: =ROUND((간접!$S$124*팀별실적!R26)/팀별실적!$R$30,-3) -> 8371000 | S33: =ROUND((간접!$T$124*팀별실적!S26)/팀별실적!$S$30,-3) -> 8371000 | T33: =SUM(Q33:S33) -> 25113000 | U33: =H33+L33+P33+T33 -> 100633000
D34: EST1 | E34: =ROUND((간접!$F$124*팀별실적!E27)/팀별실적!$E$30,-3) -> 13071000 | F34: =ROUND((간접!$G$124*팀별실적!F27)/팀별실적!$F$30,-3) -> 12546000 | G34: =ROUND((간접!$H$124*팀별실적!G27)/팀별실적!$G$30,-3) -> 12546000 | H34: =SUM(E34:G34) -> 38163000 | I34: =ROUND((간접!$J$124*팀별실적!I27)/팀별실적!$I$30,-3) -> 12546000 | J34: =ROUND((간접!$K$124*팀별실적!J27)/팀별실적!$J$30,-3) -> 12546000 | K34: =ROUND((간접!$L$124*팀별실적!K27)/팀별실적!$K$30,-3) -> 12546000 | L34: =SUM(I34:K34) -> 37638000 | M34: =ROUND((간접!$N$124*팀별실적!M27)/팀별실적!$M$30,-3) -> 12546000 | N34: =ROUND((간접!$O$124*팀별실적!N27)/팀별실적!$N$30,-3) -> 12546000 | O34: =ROUND((간접!$P$124*팀별실적!O27)/팀별실적!$O$30,-3) -> 12546000 | P34: =SUM(M34:O34) -> 37638000 | Q34: =ROUND((간접!$R$124*팀별실적!Q27)/팀별실적!$Q$30,-3) -> 12546000 | R34: =ROUND((간접!$S$124*팀별실적!R27)/팀별실적!$R$30,-3) -> 12546000 | S34: =ROUND((간접!$T$124*팀별실적!S27)/팀별실적!$S$30,-3) -> 12546000 | T34: =SUM(Q34:S34) -> 37638000 | U34: =H34+L34+P34+T34 -> 151077000
D35: EST2 | E35: =ROUND((간접!$F$124*팀별실적!E28)/팀별실적!$E$30,-3) -> 9196000 | F35: =ROUND((간접!$G$124*팀별실적!F28)/팀별실적!$F$30,-3) -> 8827000 | G35: =ROUND((간접!$H$124*팀별실적!G28)/팀별실적!$G$30,-3) -> 8827000 | H35: =SUM(E35:G35) -> 26850000 | I35: =ROUND((간접!$J$124*팀별실적!I28)/팀별실적!$I$30,-3) -> 8827000 | J35: =ROUND((간접!$K$124*팀별실적!J28)/팀별실적!$J$30,-3) -> 8827000 | K35: =ROUND((간접!$L$124*팀별실적!K28)/팀별실적!$K$30,-3) -> 8827000 | L35: =SUM(I35:K35) -> 26481000 | M35: =ROUND((간접!$N$124*팀별실적!M28)/팀별실적!$M$30,-3) -> 8827000 | N35: =ROUND((간접!$O$124*팀별실적!N28)/팀별실적!$N$30,-3) -> 8827000 | O35: =ROUND((간접!$P$124*팀별실적!O28)/팀별실적!$O$30,-3) -> 8827000 | P35: =SUM(M35:O35) -> 26481000 | Q35: =ROUND((간접!$R$124*팀별실적!Q28)/팀별실적!$Q$30,-3) -> 8827000 | R35: =ROUND((간접!$S$124*팀별실적!R28)/팀별실적!$R$30,-3) -> 8827000 | S35: =ROUND((간접!$T$124*팀별실적!S28)/팀별실적!$S$30,-3) -> 8827000 | T35: =SUM(Q35:S35) -> 26481000 | U35: =H35+L35+P35+T35 -> 106293000
D36: EST3 | E36: =ROUND((간접!$F$124*팀별실적!E29)/팀별실적!$E$30,-3) -> 4892000 | F36: =ROUND((간접!$G$124*팀별실적!F29)/팀별실적!$F$30,-3) -> 4696000 | G36: =ROUND((간접!$H$124*팀별실적!G29)/팀별실적!$G$30,-3) -> 4696000 | H36: =SUM(E36:G36) -> 14284000 | I36: =ROUND((간접!$J$124*팀별실적!I29)/팀별실적!$I$30,-3) -> 4696000 | J36: =ROUND((간접!$K$124*팀별실적!J29)/팀별실적!$J$30,-3) -> 4696000 | K36: =ROUND((간접!$L$124*팀별실적!K29)/팀별실적!$K$30,-3) -> 4696000 | L36: =SUM(I36:K36) -> 14088000 | M36: =ROUND((간접!$N$124*팀별실적!M29)/팀별실적!$M$30,-3) -> 4696000 | N36: =ROUND((간접!$O$124*팀별실적!N29)/팀별실적!$N$30,-3) -> 4696000 | O36: =ROUND((간접!$P$124*팀별실적!O29)/팀별실적!$O$30,-3) -> 4696000 | P36: =SUM(M36:O36) -> 14088000 | Q36: =ROUND((간접!$R$124*팀별실적!Q29)/팀별실적!$Q$30,-3) -> 4696000 | R36: =ROUND((간접!$S$124*팀별실적!R29)/팀별실적!$R$30,-3) -> 4696000 | S36: =ROUND((간접!$T$124*팀별실적!S29)/팀별실적!$S$30,-3) -> 4696000 | T36: =SUM(Q36:S36) -> 14088000 | U36: =H36+L36+P36+T36 -> 56548000
B37: 소계 | E37: =SUM(E31:E36) -> 59335000 | F37: =SUM(F31:F36) -> 57320000 | G37: =SUM(G31:G36) -> 57320000 | H37: =SUM(H31:H36) -> 173975000 | I37: =SUM(I31:I36) -> 57320000 | J37: =SUM(J31:J36) -> 57320000 | K37: =SUM(K31:K36) -> 57320000 | L37: =SUM(L31:L36) -> 171960000 | ... U37: =SUM(U31:U36) -> 689855000
B38: 계 | E38: =E37+E30 -> 258668000 | F38: =F37+F30 -> 257633000 | G38: =G37+G30 -> 257633000 | H38: =H37+H30 -> 773934000 | I38: =I37+I30 -> 257633000 | J38: =J37+J30 -> 257633000 | K38: =K37+K30 -> 257633000 | L38: =L37+L30 -> 772899000 | ... U38: =U37+U30 -> 3092631000
B39: 전체경비 | D39: 예산 | H39: 1241410000 | L39: 1269244000 | P39: 1308090000 | T39: 1225641000 | U39: =T39+P39+L39+H39 -> 5044385000
B40: 영업이익 | D40: SDT | E40: =E17-E24-E31 -> -41591000 | F40: =F17-F24-F31 -> -12841000 | G40: =G17-G24-G31 -> -12841000 | H40: =SUM(E40:G40) -> -67273000 | I40: =I17-I24-I31 -> -12841000 | J40: =J17-J24-J31 -> -12841000 | K40: =K17-K24-K31 -> -12841000 | L40: =SUM(I40:K40) -> -38523000 | M40: =M17-M24-M31 -> -12841000 | N40: =N17-N24-N31 -> -12841000 | O40: =O17-O24-O31 -> -12841000 | P40: =SUM(M40:O40) -> -38523000 | Q40: =Q17-Q24-Q31 -> -12841000 | R40: =R17-R24-R31 -> -12841000 | S40: =S17-S24-S31 -> -12841000 | T40: =SUM(Q40:S40) -> -38523000 | U40: =H40+L40+P40+T40 -> -182842000
...

Sheet SDT
F1: 1월 | G1: 2월 | H1: 3월 | I1: Q1 | J1: 4월 | K1: 5월 | L1: 6월 | M1: Q2 | N1: 7월 | O1: 8월 | P1: 9월 | Q1: Q3 | R1: 10월 | S1: 11월 | T1: 12월 | U1: Q4 | V1: 2026
F2: Actual | G2: Actual | H2: Actual | I2: Total | J2: Actual | K2: Actual | L2: Actual | M2: Total | N2: Actual | O2: Actual | P2: Actual | Q2: Total | R2: Actual | S2: Actual | T2: Actual | U2: Total | V2: Total
A3: 매 출
B4: Solution Business
D5: Lease | E5: 1 | I5: =H5+G5+F5 -> 0 | M5: =L5+K5+J5 -> 0 | Q5: =P5+O5+N5 -> 0 | U5: =T5+S5+R5 -> 0 | V5: =U5+Q5+M5+I5 -> 0
D6: E&S | E6: 1 | I6: =H6+G6+F6 -> 0 | M6: =L6+K6+J6 -> 0 | Q6: =P6+O6+N6 -> 0 | U6: =T6+S6+R6 -> 0 | V6: =U6+Q6+M6+I6 -> 0
D7: Paid-up | E7: 1 | I7: =H7+G7+F7 -> 0 | M7: =L7+K7+J7 -> 0 | Q7: =P7+O7+N7 -> 0 | U7: =T7+S7+R7 -> 0 | V7: =U7+Q7+M7+I7 -> 0
D8: 기타_HW Transfer | I8: =H8+G8+F8 -> 0 | M8: =L8+K8+J8 -> 0 | Q8: =P8+O8+N8 -> 0 | U8: =T8+S8+R8 -> 0 | V8: =U8+Q8+M8+I8 -> 0
D9: Service | F9: 1600000 | G9: 30000000 | H9: 30000000 | I9: =H9+G9+F9 -> 61600000 | J9: 30000000 | K9: 30000000 | L9: 30000000 | M9: =L9+K9+J9 -> 90000000 | N9: 30000000 | O9: 30000000 | P9: 30000000 | Q9: =P9+O9+N9 -> 90000000 | R9: 30000000 | S9: 30000000 | T9: 30000000 | U9: =T9+S9+R9 -> 90000000 | V9: =U9+Q9+M9+I9 -> 331600000
D10: Seminar/Training | F10: 0 | I10: =H10+G10+F10 -> 0 | M10: =L10+K10+J10 -> 0 | Q10: =P10+O10+N10 -> 0 | U10: =T10+S10+R10 -> 0 | V10: =U10+Q10+M10+I10 -> 0
A12: 매 출 합 계 | F12: =SUM(F5:F10) -> 1600000 | G12: =SUM(G5:G10) -> 30000000 | H12: =SUM(H5:H10) -> 30000000 | I12: =SUM(I5:I10) -> 61600000 | J12: =SUM(J5:J10) -> 30000000 | K12: =SUM(K5:K10) -> 30000000 | L12: =SUM(L5:L10) -> 30000000 | M12: =SUM(M5:M10) -> 90000000 | ... V12: =SUM(V5:V10) -> 331600000
A14: 매 출 원 가
C15: Royalty
D16: MSC Software | E16: 0 | I16: =H16+G16+F16 -> 0 | M16: =L16+K16+J16 -> 0 | Q16: =P16+O16+N16 -> 0 | U16: =T16+S16+R16 -> 0 | V16: =U16+Q16+M16+I16 -> 0
D17: Altair Software | I17: =H17+G17+F17 -> 0 | M17: =L17+K17+J17 -> 0 | Q17: =P17+O17+N17 -> 0 | U17: =T17+S17+R17 -> 0 | V17: =U17+Q17+M17+I17 -> 0
D18: SVD Software | I18: =H18+G18+F18 -> 0 | M18: =L18+K18+J18 -> 0 | Q18: =P18+O18+N18 -> 0 | U18: =T18+S18+R18 -> 0 | V18: =U18+Q18+M18+I18 -> 0
D19: TSV+KTM+그외 | I19: =H19+G19+F19 -> 0 | M19: =L19+K19+J19 -> 0 | Q19: =P19+O19+N19 -> 0 | U19: =T19+S19+R19 -> 0 | V19: =U19+Q19+M19+I19 -> 0
D20: 기타_System | E20: 0 | I20: =H20+G20+F20 -> 0 | M20: =L20+K20+J20 -> 0 | Q20: =P20+O20+N20 -> 0 | U20: =T20+S20+R20 -> 0 | V20: =U20+Q20+M20+I20 -> 0
C21: Outside Consultant | I21: =H21+G21+F21 -> 0 | M21: =L21+K21+J21 -> 0 | Q21: =P21+O21+N21 -> 0 | U21: =T21+S21+R21 -> 0 | V21: =U21+Q21+M21+I21 -> 0
C22: Finder commission | I22: =H22+G22+F22 -> 0 | M22: =L22+K22+J22 -> 0 | Q22: =P22+O22+N22 -> 0 | U22: =T22+S22+R22 -> 0 | V22: =U22+Q22+M22+I22 -> 0
C23: S/W+H/W 감가상각 | F23: 23000 | G23: 20000 | H23: 20000 | I23: =H23+G23+F23 -> 63000 | J23: 20000 | K23: 20000 | L23: 20000 | M23: =L23+K23+J23 -> 60000 | N23: 20000 | O23: 20000 | P23: 20000 | Q23: =P23+O23+N23 -> 60000 | R23: 20000 | S23: 20000 | T23: 20000 | U23: =T23+S23+R23 -> 60000 | V23: =U23+Q23+M23+I23 -> 243000
C24: 지급수수료_기타+임차료 | F24: =30000+33000 -> 63000 | G24: 60000 | H24: 60000 | I24: =H24+G24+F24 -> 183000 | J24: 60000 | K24: 60000 | L24: 60000 | M24: =L24+K24+J24 -> 180000 | N24: 60000 | O24: 60000 | P24: 60000 | Q24: =P24+O24+N24 -> 180000 | R24: 60000 | S24: 60000 | T24: 60000 | U24: =T24+S24+R24 -> 180000 | V24: =U24+Q24+M24+I24 -> 723000
C25: 보증보험+세금과공과 | E25: 0 | I25: =H25+G25+F25 -> 0 | M25: =L25+K25+J25 -> 0 | Q25: =P25+O25+N25 -> 0 | U25: =T25+S25+R25 -> 0 | V25: =U25+Q25+M25+I25 -> 0
A26: 매 출 원 가 합 계 | F26: =SUM(F16:F25) -> 86000 | G26: =SUM(G16:G25) -> 80000 | H26: =SUM(H16:H25) -> 80000 | I26: =SUM(I16:I25) -> 246000 | J26: =SUM(J16:J25) -> 80000 | K26: =SUM(K16:K25) -> 80000 | L26: =SUM(L16:L25) -> 80000 | M26: =SUM(M16:M25) -> 240000 | ... V26: =SUM(V16:V25) -> 966000
A28: 매 출 이 익 (%)
C29: 총 매출이익 | F29: =F12-F26 -> 1514000 | G29: =G12-G26 -> 29920000 | H29: =H12-H26 -> 29920000 | I29: =I12-I26 -> 61354000 | J29: =J12-J26 -> 29920000 | K29: =K12-K26 -> 29920000 | L29: =L12-L26 -> 29920000 | M29: =M12-M26 -> 89760000 | ... V29: =V12-V26 -> 330634000
D30: 총매출이익률 | F30: =IF(F12=0,0,F29/F12) -> 0.94625 | G30: =IF(G12=0,0,G29/G12) -> 0.99733333 | H30: =IF(H12=0,0,H29/H12) -> 0.99733333 | I30: =IF(I12=0,0,I29/I12) -> 0.99600649 | J30: =IF(J12=0,0,J29/J12) -> 0.99733333 | K30: =IF(K12=0,0,K29/K12) -> 0.99733333 | L30: =IF(L12=0,0,L29/L12) -> 0.99733333 | M30: =IF(M12=0,0,M29/M12) -> 0.99733333 | ... V30: =IF(V12=0,0,V29/V12) -> 0.99708685
A31: CONTROLLABLE EXPENSE
C32: Salary & Wages
D33: 직원급여 | E33: 0 | F33: 20000000 | G33: 20000000 | H33: 20000000 | I33: =SUM(F33:H33) -> 60000000 | J33: 20000000 | K33: 20000000 | L33: 20000000 | M33: =SUM(J33:L33) -> 60000000 | N33: 20000000 | O33: 20000000 | P33: 20000000 | Q33: =SUM(N33:P33) -> 60000000 | R33: 20000000 | S33: 20000000 | T33: 20000000 | U33: =SUM(R33:T33) -> 60000000 | V33: =I33+M33+Q33+U33 -> 240000000
D34: 특별상여 | F34: 0 | G34: 0 | H34: 0 | I34: =SUM(F34:H34) -> 0 | J34: 0 | K34: 0 | L34: 0 | M34: =SUM(J34:L34) -> 0 | N34: 0 | O34: 0 | P34: 0 | Q34: =SUM(N34:P34) -> 0 | R34: 0 | S34: 0 | T34: 0 | U34: =SUM(R34:T34) -> 0 | V34: =I34+M34+Q34+U34 -> 0
D35: 기타-연차 | E35: 0 | I35: =SUM(F35:H35) -> 0 | M35: =SUM(J35:L35) -> 0 | Q35: =SUM(N35:P35) -> 0 | U35: =SUM(R35:T35) -> 0 | V35: =I35+M35+Q35+U35 -> 0
D36: 퇴직급여 | E36: 0 | F36: 3000000 | G36: 3000000 | H36: 3000000 | I36: =SUM(F36:H36) -> 9000000 | J36: 3000000 | K36: 3000000 | L36: 3000000 | M36: =SUM(J36:L36) -> 9000000 | N36: 3000000 | O36: 3000000 | P36: 3000000 | Q36: =SUM(N36:P36) -> 9000000 | R36: 3000000 | S36: 3000000 | T36: 3000000 | U36: =SUM(R36:T36) -> 9000000 | V36: =I36+M36+Q36+U36 -> 36000000
B37: Total Salary & Wages | F37: =SUM(F33:F36) -> 23000000 | G37: =SUM(G33:G36) -> 23000000 | H37: =SUM(H33:H36) -> 23000000 | I37: =SUM(I33:I36) -> 69000000 | J37: =SUM(J33:J36) -> 23000000 | K37: =SUM(K33:K36) -> 23000000 | L37: =SUM(L33:L36) -> 23000000 | M37: =SUM(M33:M36) -> 69000000 | ... U37: =SUM(U33:U36) -> 69000000 | V37: =I37+M37+Q37+U37 -> 276000000
C38: Benefits
D39: 국민연금 | E39: 0 | F39: 1000000 | G39: 1000000 | H39: 1000000 | I39: =SUM(F39:H39) -> 3000000 | J39: 1000000 | K39: 1000000 | L39: 1000000 | M39: =SUM(J39:L39) -> 3000000 | N39: 1000000 | O39: 1000000 | P39: 1000000 | Q39: =SUM(N39:P39) -> 3000000 | R39: 1000000 | S39: 1000000 | T39: 1000000 | U39: =SUM(R39:T39) -> 3000000 | V39: =I39+M39+Q39+U39 -> 12000000
D40: 건강보험 | E40: 0 | F40: 1000000 | G40: 1000000 | H40: 1000000 | I40: =SUM(F40:H40) -> 3000000 | J40: 1000000 | K40: 1000000 | L40: 1000000 | M40: =SUM(J40:L40) -> 3000000 | N40: 1000000 | O40: 1000000 | P40: 1000000 | Q40: =SUM(N40:P40) -> 3000000 | R40: 1000000 | S40: 1000000 | T40: 1000000 | U40: =SUM(R40:T40) -> 3000000 | V40: =I40+M40+Q40+U40 -> 12000000
D41: 고용보험 | E41: 0 | F41: 200000 | G41: 200000 | H41: 200000 | I41: =SUM(F41:H41) -> 600000 | J41: 200000 | K41: 200000 | L41: 200000 | M41: =SUM(J41:L41) -> 600000 | N41: 200000 | O41: 200000 | P41: 200000 | Q41: =SUM(N41:P41) -> 600000 | R41: 200000 | S41: 200000 | T41: 200000 | U41: =SUM(R41:T41) -> 600000 | V41: =I41+M41+Q41+U41 -> 2400000
D42: 산재보험 | E42: 0 | F42: 120000 | G42: 120000 | H42: 120000 | I42: =SUM(F42:H42) -> 360000 | J42: 120000 | K42: 120000 | L42: 120000 | M42: =SUM(J42:L42) -> 360000 | N42: 120000 | O42: 120000 | P42: 120000 | Q42: =SUM(N42:P42) -> 360000 | R42: 120000 | S42: 120000 | T42: 120000 | U42: =SUM(R42:T42) -> 360000 | V42: =I42+M42+Q42+U42 -> 1440000
D43: 야근식대 | E43: 0 | F43: 8000 | G43: 8000 | H43: 8000 | I43: =SUM(F43:H43) -> 24000 | J43: 8000 | K43: 8000 | L43: 8000 | M43: =SUM(J43:L43) -> 24000 | N43: 8000 | O43: 8000 | P43: 8000 | Q43: =SUM(N43:P43) -> 24000 | R43: 8000 | S43: 8000 | T43: 8000 | U43: =SUM(R43:T43) -> 24000 | V43: =I43+M43+Q43+U43 -> 96000
...

Sheet TST1
F1: 1월 | G1: 2월 | H1: 3월 | I1: Q1 | J1: 4월 | K1: 5월 | L1: 6월 | M1: Q2 | N1: 7월 | O1: 8월 | P1: 9월 | Q1: Q3 | R1: 10월 | S1: 11월 | T1: 12월 | U1: Q4 | V1: 2026
F2: Actual | G2: Actual | H2: Actual | I2: Total | J2: Actual | K2: Actual | L2: Actual | M2: Total | N2: Actual | O2: Actual | P2: Actual | Q2: Total | R2: Actual | S2: Actual | T2: Actual | U2: Total | V2: Total
A3: 매 출
B4: Solution Business
D5: Lease | E5: 1 | F5: 128975000 | G5: 28000000 | H5: 28000000 | I5: =H5+G5+F5 -> 184975000 | J5: 28000000 | K5: 28000000 | L5: 28000000 | M5: =L5+K5+J5 -> 84000000 | N5: 28000000 | O5: 28000000 | P5: 28000000 | Q5: =P5+O5+N5 -> 84000000 | R5: 28000000 | S5: 28000000 | T5: 28000000 | U5: =T5+S5+R5 -> 84000000 | V5: =U5+Q5+M5+I5 -> 436975000
D6: E&S | E6: 1 | F6: 407012000 | G6: 40000000 | H6: 40000000 | I6: =H6+G6+F6 -> 487012000 | J6: 40000000 | K6: 40000000 | L6: 40000000 | M6: =L6+K6+J6 -> 120000000 | N6: 40000000 | O6: 40000000 | P6: 40000000 | Q6: =P6+O6+N6 -> 120000000 | R6: 40000000 | S6: 40000000 | T6: 40000000 | U6: =T6+S6+R6 -> 120000000 | V6: =U6+Q6+M6+I6 -> 847012000
D7: Paid-up | E7: 1 | F7: 0 | G7: 0 | H7: 0 | I7: =H7+G7+F7 -> 0 | J7: 0 | K7: 0 | L7: 0 | M7: =L7+K7+J7 -> 0 | N7: 0 | O7: 0 | P7: 0 | Q7: =P7+O7+N7 -> 0 | R7: 0 | S7: 0 | T7: 0 | U7: =T7+S7+R7 -> 0 | V7: =U7+Q7+M7+I7 -> 0
D8: 기타_HW Transfer | I8: =H8+G8+F8 -> 0 | M8: =L8+K8+J8 -> 0 | Q8: =P8+O8+N8 -> 0 | U8: =T8+S8+R8 -> 0 | V8: =U8+Q8+M8+I8 -> 0
D9: Service | I9: =H9+G9+F9 -> 0 | M9: =L9+K9+J9 -> 0 | Q9: =P9+O9+N9 -> 0 | U9: =T9+S9+R9 -> 0 | V9: =U9+Q9+M9+I9 -> 0
D10: Seminar/Training | I10: =H10+G10+F10 -> 0 | M10: =L10+K10+J10 -> 0 | Q10: =P10+O10+N10 -> 0 | U10: =T10+S10+R10 -> 0 | V10: =U10+Q10+M10+I10 -> 0
A12: 매 출 합 계 | F12: =SUM(F5:F10) -> 535987000 | G12: =SUM(G5:G10) -> 68000000 | H12: =SUM(H5:H10) -> 68000000 | I12: =SUM(I5:I10) -> 671987000 | J12: =SUM(J5:J10) -> 68000000 | K12: =SUM(K5:K10) -> 68000000 | L12: =SUM(L5:L10) -> 68000000 | M12: =SUM(M5:M10) -> 204000000 | ... V12: =SUM(V5:V10) -> 1283987000
A14: 매 출 원 가
C15: Royalty
D16: MSC Software | E16: 0 | F16: 75564000 | G16: 25000000 | H16: 25000000 | I16: =H16+G16+F16 -> 125564000 | J16: 25000000 | K16: 25000000 | L16: 25000000 | M16: =L16+K16+J16 -> 75000000 | N16: 25000000 | O16: 25000000 | P16: 25000000 | Q16: =P16+O16+N16 -> 75000000 | R16: 25000000 | S16: 25000000 | T16: 25000000 | U16: =T16+S16+R16 -> 75000000 | V16: =U16+Q16+M16+I16 -> 350564000
D17: SVD Software | F17: 157978000 | G17: 5000000 | H17: 5000000 | I17: =H17+G17+F17 -> 167978000 | J17: 5000000 | K17: 5000000 | L17: 5000000 | M17: =L17+K17+J17 -> 15000000 | N17: 5000000 | O17: 5000000 | P17: 5000000 | Q17: =P17+O17+N17 -> 15000000 | R17: 5000000 | S17: 5000000 | T17: 5000000 | U17: =T17+S17+R17 -> 15000000 | V17: =U17+Q17+M17+I17 -> 212978000
D18: TechSoft3D | I18: =H18+G18+F18 -> 0 | M18: =L18+K18+J18 -> 0 | Q18: =P18+O18+N18 -> 0 | U18: =T18+S18+R18 -> 0 | V18: =U18+Q18+M18+I18 -> 0
D19: TSV+KTM+그외 | I19: =H19+G19+F19 -> 0 | M19: =L19+K19+J19 -> 0 | Q19: =P19+O19+N19 -> 0 | U19: =T19+S19+R19 -> 0 | V19: =U19+Q19+M19+I19 -> 0
D20: 기타_System | E20: 0 | I20: =H20+G20+F20 -> 0 | M20: =L20+K20+J20 -> 0 | Q20: =P20+O20+N20 -> 0 | U20: =T20+S20+R20 -> 0 | V20: =U20+Q20+M20+I20 -> 0
C21: Outside Consultant | I21: =H21+G21+F21 -> 0 | M21: =L21+K21+J21 -> 0 | Q21: =P21+O21+N21 -> 0 | U21: =T21+S21+R21 -> 0 | V21: =U21+Q21+M21+I21 -> 0
C22: Finder commission | I22: =H22+G22+F22 -> 0 | M22: =L22+K22+J22 -> 0 | Q22: =P22+O22+N22 -> 0 | U22: =T22+S22+R22 -> 0 | V22: =U22+Q22+M22+I22 -> 0
C23: S/W+H/W 감가상각 | F23: 57000 | G23: 57000 | H23: 57000 | I23: =H23+G23+F23 -> 171000 | J23: 57000 | K23: 57000 | L23: 57000 | M23: =L23+K23+J23 -> 171000 | N23: 57000 | O23: 57000 | P23: 57000 | Q23: =P23+O23+N23 -> 171000 | R23: 57000 | S23: 57000 | T23: 57000 | U23: =T23+S23+R23 -> 171000 | V23: =U23+Q23+M23+I23 -> 684000
C24: 지급수수료_기타+임차료 | F24: =938000 -> 938000 | G24: =938000 -> 938000 | H24: =938000 -> 938000 | I24: =H24+G24+F24 -> 2814000 | J24: =938000 -> 938000 | K24: =938000 -> 938000 | L24: =938000 -> 938000 | M24: =L24+K24+J24 -> 2814000 | N24: =938000 -> 938000 | O24: =938000 -> 938000 | P24: =938000 -> 938000 | Q24: =P24+O24+N24 -> 2814000 | R24: =938000 -> 938000 | S24: =938000 -> 938000 | T24: =938000 -> 938000 | U24: =T24+S24+R24 -> 2814000 | V24: =U24+Q24+M24+I24 -> 11256000
C25: 보증보험+세금과공과 | E25: 0 | I25: =H25+G25+F25 -> 0 | M25: =L25+K25+J25 -> 0 | Q25: =P25+O25+N25 -> 0 | U25: =T25+S25+R25 -> 0 | V25: =U25+Q25+M25+I25 -> 0
A26: 매 출 원 가 합 계 | F26: =SUM(F16:F25) -> 234537000 | G26: =SUM(G16:G25) -> 30995000 | H26: =SUM(H16:H25) -> 30995000 | I26: =SUM(I16:I25) -> 296527000 | J26: =SUM(J16:J25) -> 30995000 | K26: =SUM(K16:K25) -> 30995000 | L26: =SUM(L16:L25) -> 30995000 | M26: =SUM(M16:M25) -> 92985000 | ... V26: =SUM(V16:V25) -> 575482000
A28: 매 출 이 익 (%)
C29: 총 매출이익 | F29: =F12-F26 -> 301450000 | G29: =G12-G26 -> 37005000 | H29: =H12-H26 -> 37005000 | I29: =I12-I26 -> 375460000 | J29: =J12-J26 -> 37005000 | K29: =K12-K26 -> 37005000 | L29: =L12-L26 -> 37005000 | M29: =M12-M26 -> 111015000 | ... V29: =V12-V26 -> 708505000
D30: 총매출이익률 | F30: =IF(F12=0,0,F29/F12) -> 0.56242036 | G30: =IF(G12=0,0,G29/G12) -> 0.54419118 | H30: =IF(H12=0,0,H29/H12) -> 0.54419118 | I30: =IF(I12=0,0,I29/I12) -> 0.55873105 | J30: =IF(J12=0,0,J29/J12) -> 0.54419118 | K30: =IF(K12=0,0,K29/K12) -> 0.54419118 | L30: =IF(L12=0,0,L29/L12) -> 0.54419118 | M30: =IF(M12=0,0,M29/M12) -> 0.54419118 | ... V30: =IF(V12=0,0,V29/V12) -> 0.55180076
A31: CONTROLLABLE EXPENSE
C32: Salary & Wages
D33: 직원급여 | E33: 0 | F33: 18000000 | G33: 18000000 | H33: 18000000 | I33: =SUM(F33:H33) -> 54000000 | J33: 18000000 | K33: 18000000 | L33: 18000000 | M33: =SUM(J33:L33) -> 54000000 | N33: 18000000 | O33: 18000000 | P33: 18000000 | Q33: =SUM(N33:P33) -> 54000000 | R33: 18000000 | S33: 18000000 | T33: 18000000 | U33: =SUM(R33:T33) -> 54000000 | V33: =I33+M33+Q33+U33 -> 216000000
D34: 특별상여 | F34: 0 | G34: 0 | H34: 0 | I34: =SUM(F34:H34) -> 0 | J34: 0 | K34: 0 | L34: 0 | M34: =SUM(J34:L34) -> 0 | N34: 0 | O34: 0 | P34: 0 | Q34: =SUM(N34:P34) -> 0 | R34: 0 | S34: 0 | T34: 0 | U34: =SUM(R34:T34) -> 0 | V34: =I34+M34+Q34+U34 -> 0
D35: 기타-연차 | E35: 0 | I35: =SUM(F35:H35) -> 0 | M35: =SUM(J35:L35) -> 0 | Q35: =SUM(N35:P35) -> 0 | U35: =SUM(R35:T35) -> 0 | V35: =I35+M35+Q35+U35 -> 0
D36: 퇴직급여 | E36: 0 | F36: 2000000 | G36: 2000000 | H36: 2000000 | I36: =SUM(F36:H36) -> 6000000 | J36: 2000000 | K36: 2000000 | L36: 2000000 | M36: =SUM(J36:L36) -> 6000000 | N36: 2000000 | O36: 2000000 | P36: 2000000 | Q36: =SUM(N36:P36) -> 6000000 | R36: 2000000 | S36: 2000000 | T36: 2000000 | U36: =SUM(R36:T36) -> 6000000 | V36: =I36+M36+Q36+U36 -> 24000000
B37: Total Salary & Wages | F37: =SUM(F33:F36) -> 20000000 | G37: =SUM(G33:G36) -> 20000000 | H37: =SUM(H33:H36) -> 20000000 | I37: =SUM(I33:I36) -> 60000000 | J37: =SUM(J33:J36) -> 20000000 | K37: =SUM(K33:K36) -> 20000000 | L37: =SUM(L33:L36) -> 20000000 | M37: =SUM(M33:M36) -> 60000000 | ... U37: =SUM(U33:U36) -> 60000000 | V37: =I37+M37+Q37+U37 -> 240000000
C38: Benefits
D39: 국민연금 | E39: 0 | F39: 500000 | G39: 500000 | H39: 500000 | I39: =SUM(F39:H39) -> 1500000 | J39: 500000 | K39: 500000 | L39: 500000 | M39: =SUM(J39:L39) -> 1500000 | N39: 500000 | O39: 500000 | P39: 500000 | Q39: =SUM(N39:P39) -> 1500000 | R39: 500000 | S39: 500000 | T39: 500000 | U39: =SUM(R39:T39) -> 1500000 | V39: =I39+M39+Q39+U39 -> 6000000
D40: 건강보험 | E40: 0 | F40: 1000000 | G40: 1000000 | H40: 1000000 | I40: =SUM(F40:H40) -> 3000000 | J40: 1000000 | K40: 1000000 | L40: 1000000 | M40: =SUM(J40:L40) -> 3000000 | N40: 1000000 | O40: 1000000 | P40: 1000000 | Q40: =SUM(N40:P40) -> 3000000 | R40: 1000000 | S40: 1000000 | T40: 1000000 | U40: =SUM(R40:T40) -> 3000000 | V40: =I40+M40+Q40+U40 -> 12000000
D41: 고용보험 | E41: 0 | F41: 300000 | G41: 300000 | H41: 300000 | I41: =SUM(F41:H41) -> 900000 | J41: 300000 | K41: 300000 | L41: 300000 | M41: =SUM(J41:L41) -> 900000 | N41: 300000 | O41: 300000 | P41: 300000 | Q41: =SUM(N41:P41) -> 900000 | R41: 300000 | S41: 300000 | T41: 300000 | U41: =SUM(R41:T41) -> 900000 | V41: =I41+M41+Q41+U41 -> 3600000
D42: 산재보험 | E42: 0 | F42: 100000 | G42: 100000 | H42: 100000 | I42: =SUM(F42:H42) -> 300000 | J42: 100000 | K42: 100000 | L42: 100000 | M42: =SUM(J42:L42) -> 300000 | N42: 100000 | O42: 100000 | P42: 100000 | Q42: =SUM(N42:P42) -> 300000 | R42: 100000 | S42: 100000 | T42: 100000 | U42: =SUM(R42:T42) -> 300000 | V42: =I42+M42+Q42+U42 -> 1200000
D43: 야근식대 | E43: 0 | F43: 26000 | G43: 26000 | H43: 26000 | I43: =SUM(F43:H43) -> 78000 | J43: 26000 | K43: 26000 | L43: 26000 | M43: =SUM(J43:L43) -> 78000 | N43: 26000 | O43: 26000 | P43: 26000 | Q43: =SUM(N43:P43) -> 78000 | R43: 26000 | S43: 26000 | T43: 26000 | U43: =SUM(R43:T43) -> 78000 | V43: =I43+M43+Q43+U43 -> 312000
...

Sheet TST2
F1: 1월 | G1: 2월 | H1: 3월 | I1: Q1 | J1: 4월 | K1: 5월 | L1: 6월 | M1: Q2 | N1: 7월 | O1: 8월 | P1: 9월 | Q1: Q3 | R1: 10월 | S1: 11월 | T1: 12월 | U1: Q4 | V1: 2026
F2: Actual | G2: Actual | H2: Actual | I2: Total | J2: Actual | K2: Actual | L2: Actual | M2: Total | N2: Actual | O2: Actual | P2: Actual | Q2: Total | R2: Actual | S2: Actual | T2: Actual | U2: Total | V2: Total
A3: 매 출
B4: Solution Business
D5: Lease | E5: 1 | F5: 222000000 | G5: 0 | H5: 0 | I5: =H5+G5+F5 -> 222000000 | J5: 0 | K5: 0 | L5: 0 | M5: =L5+K5+J5 -> 0 | N5: 0 | O5: 0 | P5: 0 | Q5: =P5+O5+N5 -> 0 | R5: 0 | S5: 0 | T5: 0 | U5: =T5+S5+R5 -> 0 | V5: =U5+Q5+M5+I5 -> 222000000
D6: E&S | E6: 1 | F6: 265871000 | G6: 65000000 | H6: 65000000 | I6: =H6+G6+F6 -> 395871000 | J6: 65000000 | K6: 65000000 | L6: 65000000 | M6: =L6+K6+J6 -> 195000000 | N6: 65000000 | O6: 65000000 | P6: 65000000 | Q6: =P6+O6+N6 -> 195000000 | R6: 65000000 | S6: 65000000 | T6: 65000000 | U6: =T6+S6+R6 -> 195000000 | V6: =U6+Q6+M6+I6 -> 980871000
D7: Paid-up | E7: 1 | F7: 93609000 | G7: 90000000 | H7: 90000000 | I7: =H7+G7+F7 -> 273609000 | J7: 90000000 | K7: 90000000 | L7: 90000000 | M7: =L7+K7+J7 -> 270000000 | N7: 90000000 | O7: 90000000 | P7: 90000000 | Q7: =P7+O7+N7 -> 270000000 | R7: 90000000 | S7: 90000000 | T7: 90000000 | U7: =T7+S7+R7 -> 270000000 | V7: =U7+Q7+M7+I7 -> 1083609000
D8: 기타_HW Transfer | I8: =H8+G8+F8 -> 0 | M8: =L8+K8+J8 -> 0 | Q8: =P8+O8+N8 -> 0 | U8: =T8+S8+R8 -> 0 | V8: =U8+Q8+M8+I8 -> 0
D9: Service | I9: =H9+G9+F9 -> 0 | M9: =L9+K9+J9 -> 0 | Q9: =P9+O9+N9 -> 0 | U9: =T9+S9+R9 -> 0 | V9: =U9+Q9+M9+I9 -> 0
D10: Seminar/Training | I10: =H10+G10+F10 -> 0 | M10: =L10+K10+J10 -> 0 | Q10: =P10+O10+N10 -> 0 | U10: =T10+S10+R10 -> 0 | V10: =U10+Q10+M10+I10 -> 0
A12: 매 출 합 계 | F12: =SUM(F5:F10) -> 581480000 | G12: =SUM(G5:G10) -> 155000000 | H12: =SUM(H5:H10) -> 155000000 | I12: =SUM(I5:I10) -> 891480000 | J12: =SUM(J5:J10) -> 155000000 | K12: =SUM(K5:K10) -> 155000000 | L12: =SUM(L5:L10) -> 155000000 | M12: =SUM(M5:M10) -> 465000000 | ... V12: =SUM(V5:V10) -> 2286480000
A14: 매 출 원 가
C15: Royalty
D16: MSC Software | E16: 0 | F16: 49068000 | G16: 40000000 | H16: 40000000 | I16: =H16+G16+F16 -> 129068000 | J16: 40000000 | K16: 40000000 | L16: 40000000 | M16: =L16+K16+J16 -> 120000000 | N16: 40000000 | O16: 40000000 | P16: 40000000 | Q16: =P16+O16+N16 -> 120000000 | R16: 40000000 | S16: 40000000 | T16: 40000000 | U16: =T16+S16+R16 -> 120000000 | V16: =U16+Q16+M16+I16 -> 489068000
D17: SVD Software | F17: 43358000 | G17: 38000000 | H17: 38000000 | I17: =H17+G17+F17 -> 119358000 | J17: 38000000 | K17: 38000000 | L17: 38000000 | M17: =L17+K17+J17 -> 114000000 | N17: 38000000 | O17: 38000000 | P17: 38000000 | Q17: =P17+O17+N17 -> 114000000 | R17: 38000000 | S17: 38000000 | T17: 38000000 | U17: =T17+S17+R17 -> 114000000 | V17: =U17+Q17+M17+I17 -> 461358000
D18: TechSoft3D | I18: =H18+G18+F18 -> 0 | M18: =L18+K18+J18 -> 0 | Q18: =P18+O18+N18 -> 0 | U18: =T18+S18+R18 -> 0 | V18: =U18+Q18+M18+I18 -> 0
D19: TSV+KTM+그외 | F19: 9090000 | G19: 0 | H19: 0 | I19: =H19+G19+F19 -> 9090000 | J19: 0 | K19: 0 | L19: 0 | M19: =L19+K19+J19 -> 0 | N19: 0 | O19: 0 | P19: 0 | Q19: =P19+O19+N19 -> 0 | R19: 0 | S19: 0 | T19: 0 | U19: =T19+S19+R19 -> 0 | V19: =U19+Q19+M19+I19 -> 9090000
D20: 기타_System | E20: 0 | I20: =H20+G20+F20 -> 0 | M20: =L20+K20+J20 -> 0 | Q20: =P20+O20+N20 -> 0 | U20: =T20+S20+R20 -> 0 | V20: =U20+Q20+M20+I20 -> 0
C21: Outside Consultant | I21: =H21+G21+F21 -> 0 | M21: =L21+K21+J21 -> 0 | Q21: =P21+O21+N21 -> 0 | U21: =T21+S21+R21 -> 0 | V21: =U21+Q21+M21+I21 -> 0
C22: Finder commission | I22: =H22+G22+F22 -> 0 | M22: =L22+K22+J22 -> 0 | Q22: =P22+O22+N22 -> 0 | U22: =T22+S22+R22 -> 0 | V22: =U22+Q22+M22+I22 -> 0
C23: S/W+H/W 감가상각 | I23: =H23+G23+F23 -> 0 | M23: =L23+K23+J23 -> 0 | Q23: =P23+O23+N23 -> 0 | U23: =T23+S23+R23 -> 0 | V23: =U23+Q23+M23+I23 -> 0
C24: 지급수수료_기타+임차료 | F24: 29000 | G24: 29000 | H24: 29000 | I24: =H24+G24+F24 -> 87000 | J24: 29000 | K24: 29000 | L24: 29000 | M24: =L24+K24+J24 -> 87000 | N24: 29000 | O24: 29000 | P24: 29000 | Q24: =P24+O24+N24 -> 87000 | R24: 29000 | S24: 29000 | T24: 29000 | U24: =T24+S24+R24 -> 87000 | V24: =U24+Q24+M24+I24 -> 348000
C25: 보증보험+세금과공과 | E25: 0 | I25: =H25+G25+F25 -> 0 | M25: =L25+K25+J25 -> 0 | Q25: =P25+O25+N25 -> 0 | U25: =T25+S25+R25 -> 0 | V25: =U25+Q25+M25+I25 -> 0
A26: 매 출 원 가 합 계 | F26: =SUM(F16:F25) -> 101545000 | G26: =SUM(G16:G25) -> 78029000 | H26: =SUM(H16:H25) -> 78029000 | I26: =SUM(I16:I25) -> 257603000 | J26: =SUM(J16:J25) -> 78029000 | K26: =SUM(K16:K25) -> 78029000 | L26: =SUM(L16:L25) -> 78029000 | M26: =SUM(M16:M25) -> 234087000 | ... V26: =SUM(V16:V25) -> 959864000
A28: 매 출 이 익 (%)
C29: 총 매출이익 | F29: =F12-F26 -> 479935000 | G29: =G12-G26 -> 76971000 | H29: =H12-H26 -> 76971000 | I29: =I12-I26 -> 633877000 | J29: =J12-J26 -> 76971000 | K29: =K12-K26 -> 76971000 | L29: =L12-L26 -> 76971000 | M29: =M12-M26 -> 230913000 | ... V29: =V12-V26 -> 1326616000
D30: 총매출이익률 | F30: =IF(F12=0,0,F29/F12) -> 0.82536803 | G30: =IF(G12=0,0,G29/G12) -> 0.4965871 | H30: =IF(H12=0,0,H29/H12) -> 0.4965871 | I30: =IF(I12=0,0,I29/I12) -> 0.71103895 | J30: =IF(J12=0,0,J29/J12) -> 0.4965871 | K30: =IF(K12=0,0,K29/K12) -> 0.4965871 | L30: =IF(L12=0,0,L29/L12) -> 0.4965871 | M30: =IF(M12=0,0,M29/M12) -> 0.4965871 | ... V30: =IF(V12=0,0,V29/V12) -> 0.58020013
A31: CONTROLLABLE EXPENSE
C32: Salary & Wages
D33: 직원급여 | E33: 0 | F33: 10000000 | G33: 10000000 | H33: 10000000 | I33: =SUM(F33:H33) -> 30000000 | J33: 10000000 | K33: 10000000 | L33: 10000000 | M33: =SUM(J33:L33) -> 30000000 | N33: 10000000 | O33: 10000000 | P33: 10000000 | Q33: =SUM(N33:P33) -> 30000000 | R33: 10000000 | S33: 10000000 | T33: 10000000 | U33: =SUM(R33:T33) -> 30000000 | V33: =I33+M33+Q33+U33 -> 120000000
D34: 특별상여 | F34: 0 | G34: 0 | H34: 0 | I34: =SUM(F34:H34) -> 0 | J34: 0 | K34: 0 | L34: 0 | M34: =SUM(J34:L34) -> 0 | N34: 0 | O34: 0 | P34: 0 | Q34: =SUM(N34:P34) -> 0 | R34: 0 | S34: 0 | T34: 0 | U34: =SUM(R34:T34) -> 0 | V34: =I34+M34+Q34+U34 -> 0
D35: 기타-연차 | E35: 0 | I35: =SUM(F35:H35) -> 0 | M35: =SUM(J35:L35) -> 0 | Q35: =SUM(N35:P35) -> 0 | U35: =SUM(R35:T35) -> 0 | V35: =I35+M35+Q35+U35 -> 0
D36: 퇴직급여 | E36: 0 | F36: 1500000 | G36: 1500000 | H36: 1500000 | I36: =SUM(F36:H36) -> 4500000 | J36: 1500000 | K36: 1500000 | L36: 1500000 | M36: =SUM(J36:L36) -> 4500000 | N36: 1500000 | O36: 1500000 | P36: 1500000 | Q36: =SUM(N36:P36) -> 4500000 | R36: 1500000 | S36: 1500000 | T36: 1500000 | U36: =SUM(R36:T36) -> 4500000 | V36: =I36+M36+Q36+U36 -> 18000000
B37: Total Salary & Wages | F37: =SUM(F33:F36) -> 11500000 | G37: =SUM(G33:G36) -> 11500000 | H37: =SUM(H33:H36) -> 11500000 | I37: =SUM(I33:I36) -> 34500000 | J37: =SUM(J33:J36) -> 11500000 | K37: =SUM(K33:K36) -> 11500000 | L37: =SUM(L33:L36) -> 11500000 | M37: =SUM(M33:M36) -> 34500000 | ... U37: =SUM(U33:U36) -> 34500000 | V37: =I37+M37+Q37+U37 -> 138000000
C38: Benefits
D39: 국민연금 | E39: 0 | F39: 400000 | G39: 400000 | H39: 400000 | I39: =SUM(F39:H39) -> 1200000 | J39: 400000 | K39: 400000 | L39: 400000 | M39: =SUM(J39:L39) -> 1200000 | N39: 400000 | O39: 400000 | P39: 400000 | Q39: =SUM(N39:P39) -> 1200000 | R39: 400000 | S39: 400000 | T39: 400000 | U39: =SUM(R39:T39) -> 1200000 | V39: =I39+M39+Q39+U39 -> 4800000
D40: 건강보험 | E40: 0 | F40: 200000 | G40: 200000 | H40: 200000 | I40: =SUM(F40:H40) -> 600000 | J40: 200000 | K40: 200000 | L40: 200000 | M40: =SUM(J40:L40) -> 600000 | N40: 200000 | O40: 200000 | P40: 200000 | Q40: =SUM(N40:P40) -> 600000 | R40: 200000 | S40: 200000 | T40: 200000 | U40: =SUM(R40:T40) -> 600000 | V40: =I40+M40+Q40+U40 -> 2400000
D41: 고용보험 | E41: 0 | F41: 100000 | G41: 100000 | H41: 100000 | I41: =SUM(F41:H41) -> 300000 | J41: 100000 | K41: 100000 | L41: 100000 | M41: =SUM(J41:L41) -> 300000 | N41: 100000 | O41: 100000 | P41: 100000 | Q41: =SUM(N41:P41) -> 300000 | R41: 100000 | S41: 100000 | T41: 100000 | U41: =SUM(R41:T41) -> 300000 | V41: =I41+M41+Q41+U41 -> 1200000
D42: 산재보험 | E42: 0 | F42: 50000 | G42: 50000 | H42: 50000 | I42: =SUM(F42:H42) -> 150000 | J42: 50000 | K42: 50000 | L42: 50000 | M42: =SUM(J42:L42) -> 150000 | N42: 50000 | O42: 50000 | P42: 50000 | Q42: =SUM(N42:P42) -> 150000 | R42: 50000 | S42: 50000 | T42: 50000 | U42: =SUM(R42:T42) -> 150000 | V42: =I42+M42+Q42+U42 -> 600000
D43: 야근식대 | E43: 0 | F43: 64000 | G43: 64000 | H43: 64000 | I43: =SUM(F43:H43) -> 192000 | J43: 64000 | K43: 64000 | L43: 64000 | M43: =SUM(J43:L43) -> 192000 | N43: 64000 | O43: 64000 | P43: 64000 | Q43: =SUM(N43:P43) -> 192000 | R43: 64000 | S43: 64000 | T43: 64000 | U43: =SUM(R43:T43) -> 192000 | V43: =I43+M43+Q43+U43 -> 768000
...

Sheet MKT
F1: 1월 | G1: 2월 | H1: 3월 | I1: Q1 | J1: 4월 | K1: 5월 | L1: 6월 | M1: Q2 | N1: 7월 | O1: 8월 | P1: 9월 | Q1: Q3 | R1: 10월 | S1: 11월 | T1: 12월 | U1: Q4 | V1: 2026
F2: Actual | G2: Actual | H2: Actual | I2: Total | J2: Actual | K2: Actual | L2: Actual | M2: Total | N2: Actual | O2: Actual | P2: Actual | Q2: Total | R2: Actual | S2: Actual | T2: Actual | U2: Total | V2: Total
A3: 매 출
B4: Solution Business
D5: Lease | E5: 1 | I5: =H5+G5+F5 -> 0 | M5: =L5+K5+J5 -> 0 | Q5: =P5+O5+N5 -> 0 | U5: =T5+S5+R5 -> 0 | V5: =U5+Q5+M5+I5 -> 0
D6: E&S | E6: 1 | I6: =H6+G6+F6 -> 0 | M6: =L6+K6+J6 -> 0 | Q6: =P6+O6+N6 -> 0 | U6: =T6+S6+R6 -> 0 | V6: =U6+Q6+M6+I6 -> 0
D7: Paid-up | E7: 1 | I7: =H7+G7+F7 -> 0 | M7: =L7+K7+J7 -> 0 | Q7: =P7+O7+N7 -> 0 | U7: =T7+S7+R7 -> 0 | V7: =U7+Q7+M7+I7 -> 0
D8: 기타_HW Transfer | I8: =H8+G8+F8 -> 0 | M8: =L8+K8+J8 -> 0 | Q8: =P8+O8+N8 -> 0 | U8: =T8+S8+R8 -> 0 | V8: =U8+Q8+M8+I8 -> 0
D9: Service | I9: =H9+G9+F9 -> 0 | M9: =L9+K9+J9 -> 0 | Q9: =P9+O9+N9 -> 0 | U9: =T9+S9+R9 -> 0 | V9: =U9+Q9+M9+I9 -> 0
D10: Seminar/Training | I10: =H10+G10+F10 -> 0 | M10: =L10+K10+J10 -> 0 | Q10: =P10+O10+N10 -> 0 | U10: =T10+S10+R10 -> 0 | V10: =U10+Q10+M10+I10 -> 0
A12: 매 출 합 계 | F12: =SUM(F5:F10) -> 0 | G12: =SUM(G5:G10) -> 0 | H12: =SUM(H5:H10) -> 0 | I12: =SUM(I5:I10) -> 0 | J12: =SUM(J5:J10) -> 0 | K12: =SUM(K5:K10) -> 0 | L12: =SUM(L5:L10) -> 0 | M12: =SUM(M5:M10) -> 0 | ... V12: =SUM(V5:V10) -> 0
A14: 매 출 원 가
C15: Royalty
D16: MSC Software | E16: 0 | I16: =H16+G16+F16 -> 0 | M16: =L16+K16+J16 -> 0 | Q16: =P16+O16+N16 -> 0 | U16: =T16+S16+R16 -> 0 | V16: =U16+Q16+M16+I16 -> 0
D17: SVD Software | I17: =H17+G17+F17 -> 0 | M17: =L17+K17+J17 -> 0 | Q17: =P17+O17+N17 -> 0 | U17: =T17+S17+R17 -> 0 | V17: =U17+Q17+M17+I17 -> 0
D18: TechSoft3D | I18: =H18+G18+F18 -> 0 | M18: =L18+K18+J18 -> 0 | Q18: =P18+O18+N18 -> 0 | U18: =T18+S18+R18 -> 0 | V18: =U18+Q18+M18+I18 -> 0
D19: TSV+KTM+그외 | I19: =H19+G19+F19 -> 0 | M19: =L19+K19+J19 -> 0 | Q19: =P19+O19+N19 -> 0 | U19: =T19+S19+R19 -> 0 | V19: =U19+Q19+M19+I19 -> 0
D20: 기타_System | E20: 0 | I20: =H20+G20+F20 -> 0 | M20: =L20+K20+J20 -> 0 | Q20: =P20+O20+N20 -> 0 | U20: =T20+S20+R20 -> 0 | V20: =U20+Q20+M20+I20 -> 0
C21: Outside Consultant | I21: =H21+G21+F21 -> 0 | M21: =L21+K21+J21 -> 0 | Q21: =P21+O21+N21 -> 0 | U21: =T21+S21+R21 -> 0 | V21: =U21+Q21+M21+I21 -> 0
C22: Finder commission | I22: =H22+G22+F22 -> 0 | M22: =L22+K22+J22 -> 0 | Q22: =P22+O22+N22 -> 0 | U22: =T22+S22+R22 -> 0 | V22: =U22+Q22+M22+I22 -> 0
C23: S/W+H/W 감가상각 | I23: =H23+G23+F23 -> 0 | M23: =L23+K23+J23 -> 0 | Q23: =P23+O23+N23 -> 0 | U23: =T23+S23+R23 -> 0 | V23: =U23+Q23+M23+I23 -> 0
C24: 지급수수료_기타+임차료 | I24: =H24+G24+F24 -> 0 | M24: =L24+K24+J24 -> 0 | Q24: =P24+O24+N24 -> 0 | U24: =T24+S24+R24 -> 0 | V24: =U24+Q24+M24+I24 -> 0
C25: 보증보험+세금과공과 | E25: 0 | I25: =H25+G25+F25 -> 0 | M25: =L25+K25+J25 -> 0 | Q25: =P25+O25+N25 -> 0 | U25: =T25+S25+R25 -> 0 | V25: =U25+Q25+M25+I25 -> 0
A26: 매 출 원 가 합 계 | F26: =SUM(F16:F25) -> 0 | G26: =SUM(G16:G25) -> 0 | H26: =SUM(H16:H25) -> 0 | I26: =SUM(I16:I25) -> 0 | J26: =SUM(J16:J25) -> 0 | K26: =SUM(K16:K25) -> 0 | L26: =SUM(L16:L25) -> 0 | M26: =SUM(M16:M25) -> 0 | ... V26: =SUM(V16:V25) -> 0
A28: 매 출 이 익 (%)
C29: 총 매출이익 | F29: =F12-F26 -> 0 | G29: =G12-G26 -> 0 | H29: =H12-H26 -> 0 | I29: =I12-I26 -> 0 | J29: =J12-J26 -> 0 | K29: =K12-K26 -> 0 | L29: =L12-L26 -> 0 | M29: =M12-M26 -> 0 | ... V29: =V12-V26 -> 0
D30: 총매출이익률 | F30: =IF(F12=0,0,F29/F12) -> 0 | G30: =IF(G12=0,0,G29/G12) -> 0 | H30: =IF(H12=0,0,H29/H12) -> 0 | I30: =IF(I12=0,0,I29/I12) -> 0 | J30: =IF(J12=0,0,J29/J12) -> 0 | K30: =IF(K12=0,0,K29/K12) -> 0 | L30: =IF(L12=0,0,L29/L12) -> 0 | M30: =IF(M12=0,0,M29/M12) -> 0 | ... V30: =IF(V12=0,0,V29/V12) -> 0
A31: CONTROLLABLE EXPENSE
C32: Salary & Wages
D33: 직원급여 | E33: 0 | F33: 10000000 | G33: 10000000 | H33: 10000000 | I33: =SUM(F33:H33) -> 30000000 | J33: 10000000 | K33: 10000000 | L33: 10000000 | M33: =SUM(J33:L33) -> 30000000 | N33: 10000000 | O33: 10000000 | P33: 10000000 | Q33: =SUM(N33:P33) -> 30000000 | R33: 10000000 | S33: 10000000 | T33: 10000000 | U33: =SUM(R33:T33) -> 30000000 | V33: =I33+M33+Q33+U33 -> 120000000
D34: 특별상여 | F34: 0 | G34: 0 | H34: 0 | I34: =SUM(F34:H34) -> 0 | J34: 0 | K34: 0 | L34: 0 | M34: =SUM(J34:L34) -> 0 | N34: 0 | O34: 0 | P34: 0 | Q34: =SUM(N34:P34) -> 0 | R34: 0 | S34: 0 | T34: 0 | U34: =SUM(R34:T34) -> 0 | V34: =I34+M34+Q34+U34 -> 0
D35: 기타-연차 | E35: 0 | I35: =SUM(F35:H35) -> 0 | M35: =SUM(J35:L35) -> 0 | Q35: =SUM(N35:P35) -> 0 | U35: =SUM(R35:T35) -> 0 | V35: =I35+M35+Q35+U35 -> 0
D36: 퇴직급여 | E36: 0 | F36: 1500000 | G36: 1500000 | H36: 1500000 | I36: =SUM(F36:H36) -> 4500000 | J36: 1500000 | K36: 1500000 | L36: 1500000 | M36: =SUM(J36:L36) -> 4500000 | N36: 1500000 | O36: 1500000 | P36: 1500000 | Q36: =SUM(N36:P36) -> 4500000 | R36: 1500000 | S36: 1500000 | T36: 1500000 | U36: =SUM(R36:T36) -> 4500000 | V36: =I36+M36+Q36+U36 -> 18000000
B37: Total Salary & Wages | F37: =SUM(F33:F36) -> 11500000 | G37: =SUM(G33:G36) -> 11500000 | H37: =SUM(H33:H36) -> 11500000 | I37: =SUM(I33:I36) -> 34500000 | J37: =SUM(J33:J36) -> 11500000 | K37: =SUM(K33:K36) -> 11500000 | L37: =SUM(L33:L36) -> 11500000 | M37: =SUM(M33:M36) -> 34500000 | ... U37: =SUM(U33:U36) -> 34500000 | V37: =I37+M37+Q37+U37 -> 138000000
C38: Benefits
D39: 국민연금 | E39: 0 | F39: 600000 | G39: 600000 | H39: 600000 | I39: =SUM(F39:H39) -> 1800000 | J39: 600000 | K39: 600000 | L39: 600000 | M39: =SUM(J39:L39) -> 1800000 | N39: 600000 | O39: 600000 | P39: 600000 | Q39: =SUM(N39:P39) -> 1800000 | R39: 600000 | S39: 600000 | T39: 600000 | U39: =SUM(R39:T39) -> 1800000 | V39: =I39+M39+Q39+U39 -> 7200000
D40: 건강보험 | E40: 0 | F40: 500000 | G40: 500000 | H40: 500000 | I40: =SUM(F40:H40) -> 1500000 | J40: 500000 | K40: 500000 | L40: 500000 | M40: =SUM(J40:L40) -> 1500000 | N40: 500000 | O40: 500000 | P40: 500000 | Q40: =SUM(N40:P40) -> 1500000 | R40: 500000 | S40: 500000 | T40: 500000 | U40: =SUM(R40:T40) -> 1500000 | V40: =I40+M40+Q40+U40 -> 6000000
D41: 고용보험 | E41: 0 | F41: 150000 | G41: 150000 | H41: 150000 | I41: =SUM(F41:H41) -> 450000 | J41: 150000 | K41: 150000 | L41: 150000 | M41: =SUM(J41:L41) -> 450000 | N41: 150000 | O41: 150000 | P41: 150000 | Q41: =SUM(N41:P41) -> 450000 | R41: 150000 | S41: 150000 | T41: 150000 | U41: =SUM(R41:T41) -> 450000 | V41: =I41+M41+Q41+U41 -> 1800000
D42: 산재보험 | E42: 0 | F42: 100000 | G42: 100000 | H42: 100000 | I42: =SUM(F42:H42) -> 300000 | J42: 100000 | K42: 100000 | L42: 100000 | M42: =SUM(J42:L42) -> 300000 | N42: 100000 | O42: 100000 | P42: 100000 | Q42: =SUM(N42:P42) -> 300000 | R42: 100000 | S42: 100000 | T42: 100000 | U42: =SUM(R42:T42) -> 300000 | V42: =I42+M42+Q42+U42 -> 1200000
D43: 야근식대 | E43: 0 | F43: 18000 | G43: 18000 | H43: 18000 | I43: =SUM(F43:H43) -> 54000 | J43: 18000 | K43: 18000 | L43: 18000 | M43: =SUM(J43:L43) -> 54000 | N43: 18000 | O43: 18000 | P43: 18000 | Q43: =SUM(N43:P43) -> 54000 | R43: 18000 | S43: 18000 | T43: 18000 | U43: =SUM(R43:T43) -> 54000 | V43: =I43+M43+Q43+U43 -> 216000
...

Sheet JGChoi
F1: 1월 | G1: 2월 | H1: 3월 | I1: Q1 | J1: 4월 | K1: 5월 | L1: 6월 | M1: Q2 | N1: 7월 | O1: 8월 | P1: 9월 | Q1: Q3 | R1: 10월 | S1: 11월 | T1: 12월 | U1: Q4 | V1: 2026
F2: Actual | G2: Actual | H2: Actual | I2: Total | J2: Actual | K2: Actual | L2: Actual | M2: Total | N2: Actual | O2: Actual | P2: Actual | Q2: Total | R2: Actual | S2: Actual | T2: Actual | U2: Total | V2: Total
A3: 매 출
B4: Solution Business
D5: Lease | E5: 1 | I5: =H5+G5+F5 -> 0 | M5: =L5+K5+J5 -> 0 | Q5: =P5+O5+N5 -> 0 | U5: =T5+S5+R5 -> 0 | V5: =U5+Q5+M5+I5 -> 0
D6: E&S | E6: 1 | I6: =H6+G6+F6 -> 0 | M6: =L6+K6+J6 -> 0 | Q6: =P6+O6+N6 -> 0 | U6: =T6+S6+R6 -> 0 | V6: =U6+Q6+M6+I6 -> 0
D7: Paid-up | E7: 1 | I7: =H7+G7+F7 -> 0 | M7: =L7+K7+J7 -> 0 | Q7: =P7+O7+N7 -> 0 | U7: =T7+S7+R7 -> 0 | V7: =U7+Q7+M7+I7 -> 0
D8: 기타_HW Transfer | I8: =H8+G8+F8 -> 0 | M8: =L8+K8+J8 -> 0 | Q8: =P8+O8+N8 -> 0 | U8: =T8+S8+R8 -> 0 | V8: =U8+Q8+M8+I8 -> 0
D9: Service | I9: =H9+G9+F9 -> 0 | M9: =L9+K9+J9 -> 0 | Q9: =P9+O9+N9 -> 0 | U9: =T9+S9+R9 -> 0 | V9: =U9+Q9+M9+I9 -> 0
D10: Seminar/Training | I10: =H10+G10+F10 -> 0 | M10: =L10+K10+J10 -> 0 | Q10: =P10+O10+N10 -> 0 | U10: =T10+S10+R10 -> 0 | V10: =U10+Q10+M10+I10 -> 0
A12: 매 출 합 계 | F12: =SUM(F5:F10) -> 0 | G12: =SUM(G5:G10) -> 0 | H12: =SUM(H5:H10) -> 0 | I12: =SUM(I5:I10) -> 0 | J12: =SUM(J5:J10) -> 0 | K12: =SUM(K5:K10) -> 0 | L12: =SUM(L5:L10) -> 0 | M12: =SUM(M5:M10) -> 0 | ... V12: =SUM(V5:V10) -> 0
A14: 매 출 원 가
C15: Royalty
D16: MSC Software | E16: 0 | I16: =H16+G16+F16 -> 0 | M16: =L16+K16+J16 -> 0 | Q16: =P16+O16+N16 -> 0 | U16: =T16+S16+R16 -> 0 | V16: =U16+Q16+M16+I16 -> 0
D17: SVD Software | I17: =H17+G17+F17 -> 0 | M17: =L17+K17+J17 -> 0 | Q17: =P17+O17+N17 -> 0 | U17: =T17+S17+R17 -> 0 | V17: =U17+Q17+M17+I17 -> 0
D18: TechSoft3D | I18: =H18+G18+F18 -> 0 | M18: =L18+K18+J18 -> 0 | Q18: =P18+O18+N18 -> 0 | U18: =T18+S18+R18 -> 0 | V18: =U18+Q18+M18+I18 -> 0
D19: TSV+KTM+그외 | I19: =H19+G19+F19 -> 0 | M19: =L19+K19+J19 -> 0 | Q19: =P19+O19+N19 -> 0 | U19: =T19+S19+R19 -> 0 | V19: =U19+Q19+M19+I19 -> 0
D20: 기타_System | E20: 0 | I20: =H20+G20+F20 -> 0 | M20: =L20+K20+J20 -> 0 | Q20: =P20+O20+N20 -> 0 | U20: =T20+S20+R20 -> 0 | V20: =U20+Q20+M20+I20 -> 0
C21: Outside Consultant | I21: =H21+G21+F21 -> 0 | M21: =L21+K21+J21 -> 0 | Q21: =P21+O21+N21 -> 0 | U21: =T21+S21+R21 -> 0 | V21: =U21+Q21+M21+I21 -> 0
C22: Finder commission | I22: =H22+G22+F22 -> 0 | M22: =L22+K22+J22 -> 0 | Q22: =P22+O22+N22 -> 0 | U22: =T22+S22+R22 -> 0 | V22: =U22+Q22+M22+I22 -> 0
C23: S/W+H/W 감가상각 | I23: =H23+G23+F23 -> 0 | M23: =L23+K23+J23 -> 0 | Q23: =P23+O23+N23 -> 0 | U23: =T23+S23+R23 -> 0 | V23: =U23+Q23+M23+I23 -> 0
C24: 지급수수료_기타+임차료 | I24: =H24+G24+F24 -> 0 | M24: =L24+K24+J24 -> 0 | Q24: =P24+O24+N24 -> 0 | U24: =T24+S24+R24 -> 0 | V24: =U24+Q24+M24+I24 -> 0
C25: 보증보험+세금과공과 | E25: 0 | I25: =H25+G25+F25 -> 0 | M25: =L25+K25+J25 -> 0 | Q25: =P25+O25+N25 -> 0 | U25: =T25+S25+R25 -> 0 | V25: =U25+Q25+M25+I25 -> 0
A26: 매 출 원 가 합 계 | F26: =SUM(F16:F25) -> 0 | G26: =SUM(G16:G25) -> 0 | H26: =SUM(H16:H25) -> 0 | I26: =SUM(I16:I25) -> 0 | J26: =SUM(J16:J25) -> 0 | K26: =SUM(K16:K25) -> 0 | L26: =SUM(L16:L25) -> 0 | M26: =SUM(M16:M25) -> 0 | ... V26: =SUM(V16:V25) -> 0
A28: 매 출 이 익 (%)
C29: 총 매출이익 | F29: =F12-F26 -> 0 | G29: =G12-G26 -> 0 | H29: =H12-H26 -> 0 | I29: =I12-I26 -> 0 | J29: =J12-J26 -> 0 | K29: =K12-K26 -> 0 | L29: =L12-L26 -> 0 | M29: =M12-M26 -> 0 | ... V29: =V12-V26 -> 0
D30: 총매출이익률 | F30: =IF(F12=0,0,F29/F12) -> 0 | G30: =IF(G12=0,0,G29/G12) -> 0 | H30: =IF(H12=0,0,H29/H12) -> 0 | I30: =IF(I12=0,0,I29/I12) -> 0 | J30: =IF(J12=0,0,J29/J12) -> 0 | K30: =IF(K12=0,0,K29/K12) -> 0 | L30: =IF(L12=0,0,L29/L12) -> 0 | M30: =IF(M12=0,0,M29/M12) -> 0 | ... V30: =IF(V12=0,0,V29/V12) -> 0
A31: CONTROLLABLE EXPENSE
C32: Salary & Wages
D33: 직원급여 | E33: 0 | F33: 10000000 | G33: 10000000 | H33: 10000000 | I33: =SUM(F33:H33) -> 30000000 | J33: 10000000 | K33: 10000000 | L33: 10000000 | M33: =SUM(J33:L33) -> 30000000 | N33: 10000000 | O33: 10000000 | P33: 10000000 | Q33: =SUM(N33:P33) -> 30000000 | R33: 10000000 | S33: 10000000 | T33: 10000000 | U33: =SUM(R33:T33) -> 30000000 | V33: =I33+M33+Q33+U33 -> 120000000
D34: 특별상여 | F34: 0 | G34: 0 | H34: 0 | I34: =SUM(F34:H34) -> 0 | J34: 0 | K34: 0 | L34: 0 | M34: =SUM(J34:L34) -> 0 | N34: 0 | O34: 0 | P34: 0 | Q34: =SUM(N34:P34) -> 0 | R34: 0 | S34: 0 | T34: 0 | U34: =SUM(R34:T34) -> 0 | V34: =I34+M34+Q34+U34 -> 0
D35: 기타-연차 | E35: 0 | I35: =SUM(F35:H35) -> 0 | M35: =SUM(J35:L35) -> 0 | Q35: =SUM(N35:P35) -> 0 | U35: =SUM(R35:T35) -> 0 | V35: =I35+M35+Q35+U35 -> 0
D36: 퇴직급여 | E36: 0 | F36: 1000000 | G36: 1000000 | H36: 1000000 | I36: =SUM(F36:H36) -> 3000000 | J36: 1000000 | K36: 1000000 | L36: 1000000 | M36: =SUM(J36:L36) -> 3000000 | N36: 1000000 | O36: 1000000 | P36: 1000000 | Q36: =SUM(N36:P36) -> 3000000 | R36: 1000000 | S36: 1000000 | T36: 1000000 | U36: =SUM(R36:T36) -> 3000000 | V36: =I36+M36+Q36+U36 -> 12000000
B37: Total Salary & Wages | F37: =SUM(F33:F36) -> 11000000 | G37: =SUM(G33:G36) -> 11000000 | H37: =SUM(H33:H36) -> 11000000 | I37: =SUM(I33:I36) -> 33000000 | J37: =SUM(J33:J36) -> 11000000 | K37: =SUM(K33:K36) -> 11000000 | L37: =SUM(L33:L36) -> 11000000 | M37: =SUM(M33:M36) -> 33000000 | ... U37: =SUM(U33:U36) -> 33000000 | V37: =I37+M37+Q37+U37 -> 132000000
C38: Benefits
